Workbook

Sheet Cover
B3: RELIANCE INDUSTRIES LIMITED
B5: EV Fast-Charging & Battery Energy Storage (BESS) New-Entry Investment Model
B11: PROJECT SUMMARY
B12: Project scope | C12: 5-year (FY2026-FY2030) unlevered project appraisal: rollout, revenue, opex, capex, D&A, working capital, FCF, NPV, IRR, payback, scenarios & sensitivity
B13: Company | C13: Reliance Industries Limited (Jio-bp / Reliance BP Mobility Ltd JV with bp; Reliance New Energy)
B14: Currency / units | C14: INR crore (₹ cr) unless stated; per-unit assumptions in ₹/kWh, ₹ lakh, ₹ cr
B15: Forecast period | C15: FY2026E - FY2030E (5 years)
B16: Base discount rate (WACC) | C16: 11.25% project discount rate (see Valuation; not an official company WACC)
B17: Model type | C17: Project (unlevered) DCF; headline NPV/IRR are 5-yr project-cash-flow based; terminal value shown only as separate sensitivity

Sheet Executive Summary
B2: EXECUTIVE SUMMARY
B3: Reliance Industries - EV Fast-Charging & BESS New-Entry (FY2026-FY2030, INR crore)
B5: INVESTMENT THESIS
B6: Reliance can extend its market-leading Jio-bp Pulse network (701 sites / 5,750 points at FY25) into incremental fast-charging plus co-located battery storage, leveraging RBML fuel-retail real estate, a 95% DC-fast / 96%-uptime platform, MoP's de-licensed regime and PM E-DRIVE capex subsidies. The project is capital-heavy and cash-negative during the 5-year build-out, but the long-lived asset base (8-10 yr) and a 49% EV-demand CAGR to 2030 make it value-accretive once residual (post-FY30 steady-state) cash flows are included.
B10: HEADLINE RESULTS (active scenario) | G10: Active scenario:
B11: NPV incl. residual (Rs cr) | C11: IRR incl. residual | D11: Discounted payback | G11: =Assumptions!H4 -> BASE
B12: =Valuation!D14 -> 139.23149 | C12: =Valuation!D16 -> 0.23857049 | D12: =Valuation!D18 -> 5
B14: NPV 5-yr build only (Rs cr) | C14: Profitability index | D14: FY30 EBITDA margin
B15: =Valuation!D13 -> -521.30677 | C15: =Valuation!D19 -> 1.2670817 | D15: ='Opex & EBITDA'!H24 -> 0.52300136
B17: SCENARIO FRAMING
B18: Driver | C18: Downside | D18: Base | E18: Upside
B19: New sites (5yr) | C19: =Assumptions!D8 -> 200 | D19: =Assumptions!E8 -> 350 | E19: =Assumptions!F8 -> 500
B20: Utilization FY30 | C20: =Assumptions!D16 -> 0 | D20: =Assumptions!E16 -> 0 | E20: =Assumptions!F16 -> 0
B21: Service charge FY30 (Rs/kWh) | C21: =Assumptions!D24 -> 32 | D21: =Assumptions!E24 -> 30 | E21: =Assumptions!F24 -> 27
B22: EVSE capex/charger (Rs lakh) | C22: =Assumptions!D27 -> 1.4 | D22: =Assumptions!E27 -> 1.2 | E22: =Assumptions!F27 -> 1
B23: Subsidy-eligible share | C23: =Assumptions!D31 -> 0.8 | D23: =Assumptions!E31 -> 0.8 | E23: =Assumptions!F31 -> 0.8
B24: WACC | C24: =Assumptions!D43 -> 0.13 | D24: =Assumptions!E43 -> 0.1125 | E24: =Assumptions!F43 -> 0.1
B26: RECOMMENDATION
B27: PROCEED selectively. Base case is NPV-positive including residual value with a ~24% IRR, but returns are highly sensitive to utilization and service-charge realization (see Sensitivity T1/T4). Recommend: (1) phase rollout to high-footfall RBML/highway sites to protect early utilization; (2) maximise PM E-DRIVE Cat-B subsidy capture; (3) attach BESS only where arbitrage spreads justify; (4) gate further capex on achieving >=15% utilization by FY28. On a pure 5-year build-phase basis the project is cash-negative - this is a long-duration infrastructure bet.
B32: To read all three cases set Assumptions!G4 to 1/2/3 and record the headline cards. Sensitivity tab shows continuous NPV & IRR ranges. WACC of 11.25% (base) is a project discount rate, not Reliance's official company WACC.

Sheet Source Data
B2: SOURCE DATA - Reliance FY25 financials & market/industry facts
B4: Metric / Fact | C4: Value | D4: Unit | E4: Source (see Sources tab)
B5: -- Reliance Industries FY2024-25 (consolidated) --
B6: Consolidated revenue | C6: 1071174 | D6: ₹ cr | E6: RIL FY25 results release / AR FY24-25
B7: EBITDA | C7: 183422 | D7: ₹ cr | E7: RIL FY25 results release / AR FY24-25
B8: PAT (incl. share of assoc./JV) | C8: 81309 | D8: ₹ cr | E8: RIL FY25 results release / AR FY24-25
B9: Cash profit | C9: 146917 | D9: ₹ cr | E9: RIL AR FY24-25 financial performance
B10: Gross debt | C10: 347530 | D10: ₹ cr | E10: RIL AR FY24-25 financial performance
B11: Net debt | C11: 117083 | D11: ₹ cr | E11: RIL AR FY24-25 financial performance
B12: Capex (FY25) | C12: 131107 | D12: ₹ cr | E12: RIL FY25 results release / AR FY24-25
B13: Green financing - SACE Push facilities | C13: 1 | D13: $ bn eq. | E13: RIL AR FY24-25 (green capex)
B14: -- Jio-bp / Reliance BP Mobility (RBML) --
B15: Country-wide fuel retail outlets (Jio-bp/RBML) | C15: 1916 | D15: outlets | E15: RIL FY25 results release
B16: Jio-bp Pulse live charging points (results release) | C16: 5750 | D16: points | E16: RIL FY25 results release
B17: Jio-bp Pulse unique charging sites | C17: 701 | D17: sites | E17: RIL FY25 results release
B18: Jio-bp charging points (EV page) | C18: 5000 | D18: points | E18: Jio-bp EV charging page
B19: Jio-bp charging stations (EV page) | C19: 500 | D19: stations | E19: Jio-bp EV charging page
B20: Jio-bp fast-charging network share | C20: 0.95 | D20: % | E20: Jio-bp EV charging page
B21: Jio-bp network uptime | C21: 0.96 | D21: % | E21: Jio-bp EV charging page
B22: Jio-bp top-rated charger rating deployed | C22: 480 | D22: kW | E22: Jio-bp EV charging page
B23: -- India EV charging market --
B24: EV charging stations installed (last 5 yrs) | C24: 29151 | D24: stations | E24: PIB EV charging station data
B25: of which fast chargers | C25: 8805 | D25: stations | E25: PIB EV charging station data
B26: of which slow chargers | C26: 20346 | D26: stations | E26: PIB EV charging station data
B27: Operational public charging stations | C27: 29277 | D27: stations | E27: Invest India electric mobility
B28: PM E-DRIVE allocation | C28: 2000 | D28: ₹ cr | E28: PIB PM E-DRIVE / EV charging data
B29: EV segment CAGR 2021-2030 | C29: 0.49 | D29: % | E29: Invest India electric mobility
B30: EV annual sales by 2030 (target) | C30: 17 | D30: mn units | E30: Invest India electric mobility
B31: Current EV penetration | C31: 0.05 | D31: % | E31: Invest India electric mobility
B32: EV GST rate | C32: 0.05 | D32: % | E32: Invest India electric mobility
B33: -- Ministry of Power EVCI guidelines (17 Sep 2024) --
B34: Service charge ceiling - DC fast, solar hours | C34: 11 | D34: ₹/kWh | E34: MoP EVCI guidelines 2024
B35: Service charge ceiling - DC fast, non-solar hours | C35: 13 | D35: ₹/kWh | E35: MoP EVCI guidelines 2024
B36: Land revenue-share model floor | C36: 1 | D36: ₹/kWh | E36: MoP EVCI guidelines 2024
B37: DISCOM tariff multiple - solar hours (x ACoS) | C37: 0.7 | D37: x | E37: MoP EVCI guidelines 2024
B38: DISCOM tariff multiple - non-solar hours (x ACoS) | C38: 1.3 | D38: x | E38: MoP EVCI guidelines 2024
B39: Charger standard - Level 3 | C39: 250 | D39: kW (50-250) | E39: MoP EVCI guidelines 2024
B40: Charger standard - Level 4 | C40: 500 | D40: kW (250-500) | E40: MoP EVCI guidelines 2024
B41: -- BESS economics & policy (PIB) --
B42: BESS levelised cost (recent, no VGF, 2 cycles) | C42: 2.1 | D42: ₹/kWh | E42: PIB BESS cost
...

Sheet Assumptions
B2: ASSUMPTIONS - scenario-driven inputs
B4: SCENARIO SELECTOR (1=Downside, 2=Base, 3=Upside) | G4: 2 | H4: =CHOOSE(G4,"DOWNSIDE","BASE","UPSIDE") -> BASE
B6: Assumption | C6: Unit | D6: Downside | E6: Base | F6: Upside | G6: ACTIVE | H6: Source / justification | I6: Source link
B7: ROLLOUT & NETWORK ARCHITECTURE
B8: Total NEW incremental sites added over 5 yrs | C8: sites | D8: 200 | E8: 350 | F8: 500 | G8: =CHOOSE($G$4,D8,E8,F8) -> 350 | H8: Incremental to Jio-bp FY25 base of 701 unique sites / 5,750 points; conservative new-build pace | I8: https://www.ril.com/sites/default/files/2025-04/25042025_Media_Release_RIL_Q4_FY2024_25_Financial_and_Operational_Performance.pdf
B9: Avg DC fast chargers per new site | C9: # | D9: 5 | E9: 6 | F9: 7 | G9: =CHOOSE($G$4,D9,E9,F9) -> 6 | H9: MoP Level 3/4 standards; Jio-bp 95% fast-charging positioning | I9: https://powermin.gov.in/sites/default/files/Guidelines_and_Standards_for_EVCI_dated_17_09_2024.pdf
B10: Avg rated power per charger | C10: kW | D10: 100 | E10: 120 | F10: 150 | G10: =CHOOSE($G$4,D10,E10,F10) -> 120 | H10: MoP Level 3 (50-250kW)/Level 4 (250-500kW); blended passenger+commercial | I10: https://powermin.gov.in/sites/default/files/Guidelines_and_Standards_for_EVCI_dated_17_09_2024.pdf
B11: % of new sites with co-located BESS by FY30 | C11: % | D11: 0.1 | E11: 0.2 | F11: 0.3 | G11: =CHOOSE($G$4,D11,E11,F11) -> 0.2 | H11: Selective BESS attach for peak shaving/arbitrage; NEP storage build-out | I11: https://www.pib.gov.in/PressReleasePage.aspx?PRID=1928750
B12: Avg BESS energy per attached site | C12: kWh | D12: 400 | E12: 500 | F12: 750 | G12: =CHOOSE($G$4,D12,E12,F12) -> 500 | H12: Sized for fast-charge peak buffering; editable | I12: https://www.pib.gov.in/PressReleaseIframePage.aspx?PRID=2204118&reg=3&lang=2
B13: UTILIZATION RAMP
B14: Utilization - FY26 (start) | C14: % | D14: 0.06 | E14: 0.08 | F14: 0.1 | G14: =CHOOSE($G$4,D14,E14,F14) -> 0.08 | H14: Conservative early utilization for public DC fast charging vs low current 5% EV penetration | I14: https://www.investindia.gov.in/sector/electric-mobility
B15: Utilization - FY30 (end) | C15: % | D15: 0.13 | E15: 0.18 | F15: 0.24 | G15: =CHOOSE($G$4,D15,E15,F15) -> 0.18 | H15: Ramp with 8x charging growth / 49% EV CAGR to 2030; still below saturation | I15: https://www.investindia.gov.in/sector/electric-mobility
B16: REVENUE & TARIFF
B17: Service charge - FY26 (start) | C17: ₹/kWh | D17: 9 | E17: 10 | F17: 11 | G17: =CHOOSE($G$4,D17,E17,F17) -> 10 | H17: Below MoP DC-fast ceiling ₹11/kWh solar; blended day/night | I17: https://powermin.gov.in/sites/default/files/Guidelines_and_Standards_for_EVCI_dated_17_09_2024.pdf
B18: Service charge - FY30 (end) | C18: ₹/kWh | D18: 11 | E18: 12 | F18: 12.5 | G18: =CHOOSE($G$4,D18,E18,F18) -> 12 | H18: Blended below ₹13/kWh non-solar ceiling; pricing power as utilization rises | I18: https://powermin.gov.in/sites/default/files/Guidelines_and_Standards_for_EVCI_dated_17_09_2024.pdf
B19: Electricity pass-through cost | C19: ₹/kWh | D19: 7 | E19: 7 | F19: 6.5 | G19: =CHOOSE($G$4,D19,E19,F19) -> 7 | H19: DISCOM tariff (0.7x ACoS solar/1.3x non-solar); pass-through, near-zero margin | I19: https://powermin.gov.in/sites/default/files/Guidelines_and_Standards_for_EVCI_dated_17_09_2024.pdf
B20: Land revenue share paid | C20: ₹/kWh | D20: 1 | E20: 1 | F20: 0.8 | G20: =CHOOSE($G$4,D20,E20,F20) -> 1 | H20: MoP revenue-share floor ₹1/kWh where applicable | I20: https://powermin.gov.in/sites/default/files/Guidelines_and_Standards_for_EVCI_dated_17_09_2024.pdf
B21: BESS arbitrage net spread | C21: ₹/kWh | D21: 1.5 | E21: 2 | F21: 2.8 | G21: =CHOOSE($G$4,D21,E21,F21) -> 2 | H21: Charge ~₹2.5 solar, discharge at peak; 1.5-2 cycles/day economics | I21: https://www.pib.gov.in/PressReleaseIframePage.aspx?PRID=2204118&reg=3&lang=2
B22: BESS cycles per day | C22: #/day | D22: 1 | E22: 1.5 | F22: 2 | G22: =CHOOSE($G$4,D22,E22,F22) -> 1.5 | H22: PIB market trend ~1.5 cycles/day | I22: https://www.pib.gov.in/PressReleaseIframePage.aspx?PRID=2204118&reg=3&lang=2
B23: CAPEX (gross, before subsidy)
B24: EVSE+installation capex per DC fast charger | C24: ₹ lakh | D24: 32 | E24: 30 | F24: 27 | G24: =CHOOSE($G$4,D24,E24,F24) -> 30 | H24: Hardware+install for 100-150kW DC fast charger; volume discounts in upside | I24: https://powermin.gov.in/sites/default/files/Guidelines_and_Standards_for_EVCI_dated_17_09_2024.pdf
B25: Upstream/grid capex per charger | C25: ₹ lakh | D25: 22 | E25: 20 | F25: 18 | G25: =CHOOSE($G$4,D25,E25,F25) -> 20 | H25: Transformer, cabling, metering; PM E-DRIVE upstream category | I25: https://www.pib.gov.in/PressReleasePage.aspx?PRID=2200851&reg=3&lang=1
B26: Site development capex per site | C26: ₹ lakh | D26: 60 | E26: 60 | F26: 55 | G26: =CHOOSE($G$4,D26,E26,F26) -> 60 | H26: Civil, canopy, signage at RBML/host site | I26: https://powermin.gov.in/sites/default/files/Guidelines_and_Standards_for_EVCI_dated_17_09_2024.pdf
B27: BESS capex per MWh | C27: ₹ cr/MWh | D27: 1.4 | E27: 1.2 | F27: 1 | G27: =CHOOSE($G$4,D27,E27,F27) -> 1.2 | H27: Falling cell costs; ACC PLI localisation; editable | I27: https://www.pib.gov.in/PressReleaseIframePage.aspx?PRID=2204118&reg=3&lang=2
B28: SUBSIDY (PM E-DRIVE Category B)
B29: % of new sites qualifying for Cat-B subsidy | C29: % | D29: 0 | E29: 0.25 | F29: 0.4 | G29: =CHOOSE($G$4,D29,E29,F29) -> 0.25 | H29: Eligibility depends on approved public/Govt city-highway locations | I29: https://www.pib.gov.in/PressReleasePage.aspx?PRID=2200851&reg=3&lang=1
B30: Subsidy rate on EVSE (Cat-B) | C30: % | D30: 0.7 | E30: 0.7 | F30: 0.7 | G30: =CHOOSE($G$4,D30,E30,F30) -> 0.7 | H30: PM E-DRIVE Cat-B EVSE 70% | I30: https://www.pib.gov.in/PressReleasePage.aspx?PRID=2200851&reg=3&lang=1
B31: Subsidy rate on upstream (Cat-B) | C31: % | D31: 0.8 | E31: 0.8 | F31: 0.8 | G31: =CHOOSE($G$4,D31,E31,F31) -> 0.8 | H31: PM E-DRIVE Cat-B upstream 80% | I31: https://www.pib.gov.in/PressReleasePage.aspx?PRID=2200851&reg=3&lang=1
B32: OPEX
B33: Maintenance % of gross capex p.a. | C33: % | D33: 0.05 | E33: 0.04 | F33: 0.035 | G33: =CHOOSE($G$4,D33,E33,F33) -> 0.04 | H33: Industry O&M norm for DC fast chargers | I33: https://powermin.gov.in/sites/default/files/Guidelines_and_Standards_for_EVCI_dated_17_09_2024.pdf
B34: Staff / site operations per site p.a. | C34: ₹ lakh | D34: 20 | E34: 18 | F34: 15 | G34: =CHOOSE($G$4,D34,E34,F34) -> 18 | H34: Shared staffing across host sites | I34: https://www.ril.com/sites/default/files/2025-04/25042025_Media_Release_RIL_Q4_FY2024_25_Financial_and_Operational_Performance.pdf
B35: Software/network/customer support | C35: ₹/kWh | D35: 0.85 | E35: 0.75 | F35: 0.65 | G35: =CHOOSE($G$4,D35,E35,F35) -> 0.75 | H35: CMS, payments, support per kWh dispensed | I35: https://www.jiobp.com/news/ev-charging-news-new
B36: Central SG&A % of service revenue | C36: % | D36: 0.1 | E36: 0.08 | F36: 0.06 | G36: =CHOOSE($G$4,D36,E36,F36) -> 0.08 | H36: Corporate overhead allocation | I36: https://www.ril.com/ar2024-25/financial-performance-and-review.html
B37: Insurance % of gross capex p.a. | C37: % | D37: 0.005 | E37: 0.005 | F37: 0.005 | G37: =CHOOSE($G$4,D37,E37,F37) -> 0.005 | H37: Asset insurance | I37: https://www.ril.com/ar2024-25/financial-performance-and-review.html
B38: WORKING CAPITAL, TAX, DEPRECIATION & DISCOUNT RATE
B39: Net working capital % of total revenue | C39: % | D39: 0.05 | E39: 0.04 | F39: 0.03 | G39: =CHOOSE($G$4,D39,E39,F39) -> 0.04 | H39: Receivables (fleet/credit) less payables; light NWC business | I39: https://www.ril.com/ar2024-25/financial-performance-and-review.html
B40: Corporate tax rate (incl. cess) | C40: % | D40: 0.2517 | E40: 0.2517 | F40: 0.2517 | G40: =CHOOSE($G$4,D40,E40,F40) -> 0.2517 | H40: General India corporate tax assumption (editable) | I40: https://www.ril.com/ar2024-25/financial-performance-and-review.html
B41: Depreciation life - chargers/site infra | C41: yrs | D41: 10 | E41: 10 | F41: 10 | G41: =CHOOSE($G$4,D41,E41,F41) -> 10 | H41: Straight-line useful life assumption | I41: https://www.ril.com/ar2024-25/financial-performance-and-review.html
B42: Depreciation life - BESS | C42: yrs | D42: 8 | E42: 8 | F42: 8 | G42: =CHOOSE($G$4,D42,E42,F42) -> 8 | H42: Battery useful life assumption | I42: https://www.pib.gov.in/PressReleaseIframePage.aspx?PRID=2204118&reg=3&lang=2
B43: WACC (project discount rate) | C43: % | D43: 0.13 | E43: 0.1125 | F43: 0.1 | G43: =CHOOSE($G$4,D43,E43,F43) -> 0.1125 | H43: 11.25% base for consistency with prior Reliance NPV/IRR work; not official company WACC | I43: https://www.ril.com/ar2024-25/financial-performance-and-review.html

Sheet Rollout Plan
B2: ROLLOUT PLAN - sites, chargers, BESS, ramp by year
B4: (INR crore unless stated) | D4: FY2026 | E4: FY2027 | F4: FY2028 | G4: FY2029 | H4: FY2030
B5: INCREMENTAL SITE ROLLOUT (new sites only)
B6: Annual rollout weight (% of total new sites) | D6: 0.1 | E6: 0.15 | F6: 0.2 | G6: 0.25 | H6: 0.3
B7: New sites added in year | D7: =ROUND(Assumptions!$G$8*D6,0) -> 35 | E7: =ROUND(Assumptions!$G$8*E6,0) -> 53 | F7: =ROUND(Assumptions!$G$8*F6,0) -> 70 | G7: =ROUND(Assumptions!$G$8*G6,0) -> 88 | H7: =ROUND(Assumptions!$G$8*H6,0) -> 105
B8: Cumulative new sites operating | D8: =D7 -> 35 | E8: =D8+E7 -> 88 | F8: =E8+F7 -> 158 | G8: =F8+G7 -> 246 | H8: =G8+H7 -> 351
B9: Chargers added in year | D9: =D7*Assumptions!$G$9 -> 210 | E9: =E7*Assumptions!$G$9 -> 318 | F9: =F7*Assumptions!$G$9 -> 420 | G9: =G7*Assumptions!$G$9 -> 528 | H9: =H7*Assumptions!$G$9 -> 630
B10: Cumulative chargers operating | D10: =D9 -> 210 | E10: =D10+E9 -> 528 | F10: =E10+F9 -> 948 | G10: =F10+G9 -> 1476 | H10: =G10+H9 -> 2106
B11: Avg rated power per charger (kW) | D11: =Assumptions!$G$10 -> 120 | E11: =Assumptions!$G$10 -> 120 | F11: =Assumptions!$G$10 -> 120 | G11: =Assumptions!$G$10 -> 120 | H11: =Assumptions!$G$10 -> 120
B12: Total installed capacity (MW) | D12: =D10*D11/1000 -> 25.2 | E12: =E10*E11/1000 -> 63.36 | F12: =F10*F11/1000 -> 113.76 | G12: =G10*G11/1000 -> 177.12 | H12: =H10*H11/1000 -> 252.72
B14: CO-LOCATED BESS ROLLOUT
B15: BESS attach % of cumulative sites (ramp to FY30 target) | D15: =Assumptions!$G$11*(1/5) -> 0.04 | E15: =Assumptions!$G$11*(2/5) -> 0.08 | F15: =Assumptions!$G$11*(3/5) -> 0.12 | G15: =Assumptions!$G$11*(4/5) -> 0.16 | H15: =Assumptions!$G$11*(5/5) -> 0.2
B16: Cumulative BESS-attached sites | D16: =ROUND(D8*D15,0) -> 1 | E16: =ROUND(E8*E15,0) -> 7 | F16: =ROUND(F8*F15,0) -> 19 | G16: =ROUND(G8*G15,0) -> 39 | H16: =ROUND(H8*H15,0) -> 70
B17: Cumulative BESS energy installed (MWh) | D17: =D16*Assumptions!$G$12/1000 -> 0.5 | E17: =E16*Assumptions!$G$12/1000 -> 3.5 | F17: =F16*Assumptions!$G$12/1000 -> 9.5 | G17: =G16*Assumptions!$G$12/1000 -> 19.5 | H17: =H16*Assumptions!$G$12/1000 -> 35
B18: Incremental BESS energy added (MWh) | D18: =D17 -> 0.5 | E18: =E17-D17 -> 3 | F18: =F17-E17 -> 6 | G18: =G17-F17 -> 10 | H18: =H17-G17 -> 15.5
B20: UTILIZATION RAMP (linear)
B21: Average charger utilization (%) | D21: =Assumptions!$G$14+(Assumptions!$G$15-Assumptions!$G$14)*(0/4) -> 0.08 | E21: =Assumptions!$G$14+(Assumptions!$G$15-Assumptions!$G$14)*(1/4) -> 0.105 | F21: =Assumptions!$G$14+(Assumptions!$G$15-Assumptions!$G$14)*(2/4) -> 0.13 | G21: =Assumptions!$G$14+(Assumptions!$G$15-Assumptions!$G$14)*(3/4) -> 0.155 | H21: =Assumptions!$G$14+(Assumptions!$G$15-Assumptions!$G$14)*(4/4) -> 0.18
B22: Note: New sites are incremental to the Jio-bp FY25 base of 701 unique sites and 5,750 live charging points. Rollout weights are editable (blue). Utilization and BESS attach interpolate linearly to the FY30 targets on the Assumptions tab.

Sheet Revenue Build
B2: REVENUE BUILD
B4: (INR crore unless stated) | D4: FY2026 | E4: FY2027 | F4: FY2028 | G4: FY2029 | H4: FY2030
B5: ENERGY DISPENSED
B6: Cumulative chargers operating (link) | D6: ='Rollout Plan'!D10 -> 210 | E6: ='Rollout Plan'!E10 -> 528 | F6: ='Rollout Plan'!F10 -> 948 | G6: ='Rollout Plan'!G10 -> 1476 | H6: ='Rollout Plan'!H10 -> 2106
B7: Avg rated power per charger (kW, link) | D7: ='Rollout Plan'!D11 -> 120 | E7: ='Rollout Plan'!E11 -> 120 | F7: ='Rollout Plan'!F11 -> 120 | G7: ='Rollout Plan'!G11 -> 120 | H7: ='Rollout Plan'!H11 -> 120
B8: Utilization (%, link) | D8: ='Rollout Plan'!D21 -> 0.08 | E8: ='Rollout Plan'!E21 -> 0.105 | F8: ='Rollout Plan'!F21 -> 0.13 | G8: ='Rollout Plan'!G21 -> 0.155 | H8: ='Rollout Plan'!H21 -> 0.18
B9: Energy dispensed (mn kWh) | D9: =D6*D7*24*365*D8/1000000 -> 17.66016 | E9: =E6*E7*24*365*E8/1000000 -> 58.278528 | F9: =F6*F7*24*365*F8/1000000 -> 129.54989 | G9: =G6*G7*24*365*G8/1000000 -> 240.49354 | H9: =H6*H7*24*365*H8/1000000 -> 398.4889
B10: Energy dispensed (kWh, for INR/kWh math) | D10: =D9*1000000 -> 17660160 | E10: =E9*1000000 -> 58278528 | F10: =F9*1000000 -> 1.2954989e+08 | G10: =G9*1000000 -> 240493536 | H10: =H9*1000000 -> 398488896
B12: SERVICE-CHARGE REVENUE (project revenue)
B13: Blended service charge (Rs/kWh) | D13: =Assumptions!$G$17+(Assumptions!$G$18-Assumptions!$G$17)*(0/4) -> 10 | E13: =Assumptions!$G$17+(Assumptions!$G$18-Assumptions!$G$17)*(1/4) -> 10.5 | F13: =Assumptions!$G$17+(Assumptions!$G$18-Assumptions!$G$17)*(2/4) -> 11 | G13: =Assumptions!$G$17+(Assumptions!$G$18-Assumptions!$G$17)*(3/4) -> 11.5 | H13: =Assumptions!$G$17+(Assumptions!$G$18-Assumptions!$G$17)*(4/4) -> 12
B14: Service-charge revenue (Rs cr) | D14: =D10*D13/10000000 -> 17.66016 | E14: =E10*E13/10000000 -> 61.192454 | F14: =F10*F13/10000000 -> 142.50488 | G14: =G10*G13/10000000 -> 276.56757 | H14: =H10*H13/10000000 -> 478.18668
B16: BESS ARBITRAGE REVENUE
B17: BESS energy installed (MWh, link) | D17: ='Rollout Plan'!D17 -> 0.5 | E17: ='Rollout Plan'!E17 -> 3.5 | F17: ='Rollout Plan'!F17 -> 9.5 | G17: ='Rollout Plan'!G17 -> 19.5 | H17: ='Rollout Plan'!H17 -> 35
B18: BESS throughput (mn kWh) = MWh*1000*cycles*365 | D18: =D17*1000*Assumptions!$G$22*365/1000000 -> 0.27375 | E18: =E17*1000*Assumptions!$G$22*365/1000000 -> 1.91625 | F18: =F17*1000*Assumptions!$G$22*365/1000000 -> 5.20125 | G18: =G17*1000*Assumptions!$G$22*365/1000000 -> 10.67625 | H18: =H17*1000*Assumptions!$G$22*365/1000000 -> 19.1625
B19: BESS arbitrage revenue (Rs cr) | D19: =D18*1000000*Assumptions!$G$21/10000000 -> 0.05475 | E19: =E18*1000000*Assumptions!$G$21/10000000 -> 0.38325 | F19: =F18*1000000*Assumptions!$G$21/10000000 -> 1.04025 | G19: =G18*1000000*Assumptions!$G$21/10000000 -> 2.13525 | H19: =H18*1000000*Assumptions!$G$21/10000000 -> 3.8325
B21: MEMO: PASS-THROUGH ITEMS (excluded from project revenue/FCF)
B22: Electricity pass-through (Rs cr) - memo only | D22: =D10*Assumptions!$G$19/10000000 -> 12.362112 | E22: =E10*Assumptions!$G$19/10000000 -> 40.79497 | F22: =F10*Assumptions!$G$19/10000000 -> 90.684922 | G22: =G10*Assumptions!$G$19/10000000 -> 168.34548 | H22: =H10*Assumptions!$G$19/10000000 -> 278.94223
B23: GST on service charge (Rs cr) - memo, pass-through | D23: =D14*0.18 -> 3.1788288 | E23: =E14*0.18 -> 11.014642 | F23: =F14*0.18 -> 25.650878 | G23: =G14*0.18 -> 49.782162 | H23: =H14*0.18 -> 86.073602
B25: TOTAL PROJECT REVENUE
B26: Total project revenue (service + BESS arbitrage) | D26: =D14+D19 -> 17.71491 | E26: =E14+E19 -> 61.575704 | F26: =F14+F19 -> 143.54513 | G26: =G14+G19 -> 278.70282 | H26: =H14+H19 -> 482.01918
B27: Note: Energy dispensed = chargers x rated kW x 24 x 365 x utilization. Project revenue = service-charge revenue + BESS arbitrage. Electricity and GST are shown as memo pass-throughs (near-zero margin / collected on behalf of govt) and are EXCLUDED from project revenue, EBITDA and FCF.

Sheet Opex & EBITDA
B2: OPEX & EBITDA
B4: (INR crore unless stated) | D4: FY2026 | E4: FY2027 | F4: FY2028 | G4: FY2029 | H4: FY2030
B5: REVENUE (link)
B6: Service-charge revenue (link) | D6: ='Revenue Build'!D14 -> 17.66016 | E6: ='Revenue Build'!E14 -> 61.192454 | F6: ='Revenue Build'!F14 -> 142.50488 | G6: ='Revenue Build'!G14 -> 276.56757 | H6: ='Revenue Build'!H14 -> 478.18668
B7: BESS arbitrage revenue (link) | D7: ='Revenue Build'!D19 -> 0.05475 | E7: ='Revenue Build'!E19 -> 0.38325 | F7: ='Revenue Build'!F19 -> 1.04025 | G7: ='Revenue Build'!G19 -> 2.13525 | H7: ='Revenue Build'!H19 -> 3.8325
B8: Total project revenue (link) | D8: ='Revenue Build'!D26 -> 17.71491 | E8: ='Revenue Build'!E26 -> 61.575704 | F8: ='Revenue Build'!F26 -> 143.54513 | G8: ='Revenue Build'!G26 -> 278.70282 | H8: ='Revenue Build'!H26 -> 482.01918
B10: OPERATING COSTS
B11: Energy dispensed (kWh, link) | D11: ='Revenue Build'!D10 -> 17660160 | E11: ='Revenue Build'!E10 -> 58278528 | F11: ='Revenue Build'!F10 -> 1.2954989e+08 | G11: ='Revenue Build'!G10 -> 240493536 | H11: ='Revenue Build'!H10 -> 398488896
B12: Cumulative gross capex (link) | D12: ='Capex & DA'!D25 -> 126.6 | E12: ='Capex & DA'!E25 -> 321 | F12: ='Capex & DA'!F25 -> 580.2 | G12: ='Capex & DA'!G25 -> 909 | H12: ='Capex & DA'!H25 -> 1305.6
B13: Cumulative sites operating (link) | D13: ='Rollout Plan'!D8 -> 35 | E13: ='Rollout Plan'!E8 -> 88 | F13: ='Rollout Plan'!F8 -> 158 | G13: ='Rollout Plan'!G8 -> 246 | H13: ='Rollout Plan'!H8 -> 351
B14: Maintenance (Rs cr) | D14: =D12*Assumptions!$G$33 -> 5.064 | E14: =E12*Assumptions!$G$33 -> 12.84 | F14: =F12*Assumptions!$G$33 -> 23.208 | G14: =G12*Assumptions!$G$33 -> 36.36 | H14: =H12*Assumptions!$G$33 -> 52.224
B15: Insurance (Rs cr) | D15: =D12*Assumptions!$G$37 -> 0.633 | E15: =E12*Assumptions!$G$37 -> 1.605 | F15: =F12*Assumptions!$G$37 -> 2.901 | G15: =G12*Assumptions!$G$37 -> 4.545 | H15: =H12*Assumptions!$G$37 -> 6.528
B16: Staff / site operations (Rs cr) | D16: =D13*Assumptions!$G$34/100 -> 6.3 | E16: =E13*Assumptions!$G$34/100 -> 15.84 | F16: =F13*Assumptions!$G$34/100 -> 28.44 | G16: =G13*Assumptions!$G$34/100 -> 44.28 | H16: =H13*Assumptions!$G$34/100 -> 63.18
B17: Software / network / support (Rs cr) | D17: =D11*Assumptions!$G$35/10000000 -> 1.324512 | E17: =E11*Assumptions!$G$35/10000000 -> 4.3708896 | F17: =F11*Assumptions!$G$35/10000000 -> 9.7162416 | G17: =G11*Assumptions!$G$35/10000000 -> 18.037015 | H17: =H11*Assumptions!$G$35/10000000 -> 29.886667
B18: Land revenue share (Rs cr) | D18: =D11*Assumptions!$G$20/10000000 -> 1.766016 | E18: =E11*Assumptions!$G$20/10000000 -> 5.8278528 | F18: =F11*Assumptions!$G$20/10000000 -> 12.954989 | G18: =G11*Assumptions!$G$20/10000000 -> 24.049354 | H18: =H11*Assumptions!$G$20/10000000 -> 39.84889
B19: Central SG&A (Rs cr) | D19: =D6*Assumptions!$G$36 -> 1.4128128 | E19: =E6*Assumptions!$G$36 -> 4.8953964 | F19: =F6*Assumptions!$G$36 -> 11.40039 | G19: =G6*Assumptions!$G$36 -> 22.125405 | H19: =H6*Assumptions!$G$36 -> 38.254934
B20: Total operating costs (Rs cr) | D20: =D14+D15+D16+D17+D18+D19 -> 16.500341 | E20: =E14+E15+E16+E17+E18+E19 -> 45.379139 | F20: =F14+F15+F16+F17+F18+F19 -> 88.620621 | G20: =G14+G15+G16+G17+G18+G19 -> 149.39677 | H20: =H14+H15+H16+H17+H18+H19 -> 229.92249
B22: EBITDA
B23: EBITDA (Rs cr) | D23: =D8-D20 -> 1.2145692 | E23: =E8-E20 -> 16.196566 | F23: =F8-F20 -> 54.924506 | G23: =G8-G20 -> 129.30604 | H23: =H8-H20 -> 252.09668
B24: EBITDA margin (% of project revenue) | D24: =IF(D8=0,0,D23/D8) -> 0.068561974 | E24: =IF(E8=0,0,E23/E8) -> 0.263035 | F24: =IF(F8=0,0,F23/F8) -> 0.38262885 | G24: =IF(G8=0,0,G23/G8) -> 0.46395671 | H24: =IF(H8=0,0,H23/H8) -> 0.52300136
B25: Note: EBITDA excludes electricity and GST pass-throughs (shown as memo on Revenue Build). Maintenance and insurance are % of cumulative gross capex; staff is per operating site; software/support and land revenue-share are per kWh dispensed; SG&A is % of service-charge revenue.

Sheet Capex & DA
B2: CAPEX & DEPRECIATION / AMORTISATION
B4: (INR crore unless stated) | D4: FY2026 | E4: FY2027 | F4: FY2028 | G4: FY2029 | H4: FY2030
B5: GROSS CAPEX (before subsidy) - on assets added in year
B6: Chargers added (link) | D6: ='Rollout Plan'!D9 -> 210 | E6: ='Rollout Plan'!E9 -> 318 | F6: ='Rollout Plan'!F9 -> 420 | G6: ='Rollout Plan'!G9 -> 528 | H6: ='Rollout Plan'!H9 -> 630
B7: New sites added (link) | D7: ='Rollout Plan'!D7 -> 35 | E7: ='Rollout Plan'!E7 -> 53 | F7: ='Rollout Plan'!F7 -> 70 | G7: ='Rollout Plan'!G7 -> 88 | H7: ='Rollout Plan'!H7 -> 105
B8: BESS energy added (MWh, link) | D8: ='Rollout Plan'!D18 -> 0.5 | E8: ='Rollout Plan'!E18 -> 3 | F8: ='Rollout Plan'!F18 -> 6 | G8: ='Rollout Plan'!G18 -> 10 | H8: ='Rollout Plan'!H18 -> 15.5
B9: EVSE + installation capex (Rs cr) | D9: =D6*Assumptions!$G$24/100 -> 63 | E9: =E6*Assumptions!$G$24/100 -> 95.4 | F9: =F6*Assumptions!$G$24/100 -> 126 | G9: =G6*Assumptions!$G$24/100 -> 158.4 | H9: =H6*Assumptions!$G$24/100 -> 189
B10: Upstream / grid capex (Rs cr) | D10: =D6*Assumptions!$G$25/100 -> 42 | E10: =E6*Assumptions!$G$25/100 -> 63.6 | F10: =F6*Assumptions!$G$25/100 -> 84 | G10: =G6*Assumptions!$G$25/100 -> 105.6 | H10: =H6*Assumptions!$G$25/100 -> 126
B11: Site development capex (Rs cr) | D11: =D7*Assumptions!$G$26/100 -> 21 | E11: =E7*Assumptions!$G$26/100 -> 31.8 | F11: =F7*Assumptions!$G$26/100 -> 42 | G11: =G7*Assumptions!$G$26/100 -> 52.8 | H11: =H7*Assumptions!$G$26/100 -> 63
B12: BESS capex (Rs cr) | D12: =D8*Assumptions!$G$27 -> 0.6 | E12: =E8*Assumptions!$G$27 -> 3.6 | F12: =F8*Assumptions!$G$27 -> 7.2 | G12: =G8*Assumptions!$G$27 -> 12 | H12: =H8*Assumptions!$G$27 -> 18.6
B13: Gross capex - chargers/site infra (Rs cr) | D13: =D9+D10+D11 -> 126 | E13: =E9+E10+E11 -> 190.8 | F13: =F9+F10+F11 -> 252 | G13: =G9+G10+G11 -> 316.8 | H13: =H9+H10+H11 -> 378
B14: Total gross capex (Rs cr) | D14: =D13+D12 -> 126.6 | E14: =E13+E12 -> 194.4 | F14: =F13+F12 -> 259.2 | G14: =G13+G12 -> 328.8 | H14: =H13+H12 -> 396.6
B16: SUBSIDY (PM E-DRIVE Cat-B) - reduces net capex
B17: EVSE subsidy (Rs cr) | D17: =D9*Assumptions!$G$29*Assumptions!$G$30 -> 11.025 | E17: =E9*Assumptions!$G$29*Assumptions!$G$30 -> 16.695 | F17: =F9*Assumptions!$G$29*Assumptions!$G$30 -> 22.05 | G17: =G9*Assumptions!$G$29*Assumptions!$G$30 -> 27.72 | H17: =H9*Assumptions!$G$29*Assumptions!$G$30 -> 33.075
B18: Upstream subsidy (Rs cr) | D18: =D10*Assumptions!$G$29*Assumptions!$G$31 -> 8.4 | E18: =E10*Assumptions!$G$29*Assumptions!$G$31 -> 12.72 | F18: =F10*Assumptions!$G$29*Assumptions!$G$31 -> 16.8 | G18: =G10*Assumptions!$G$29*Assumptions!$G$31 -> 21.12 | H18: =H10*Assumptions!$G$29*Assumptions!$G$31 -> 25.2
B19: Total subsidy received (Rs cr) | D19: =D17+D18 -> 19.425 | E19: =E17+E18 -> 29.415 | F19: =F17+F18 -> 38.85 | G19: =G17+G18 -> 48.84 | H19: =H17+H18 -> 58.275
B20: NET CAPEX (Rs cr) | D20: =D14-D19 -> 107.175 | E20: =E14-E19 -> 164.985 | F20: =F14-F19 -> 220.35 | G20: =G14-G19 -> 279.96 | H20: =H14-H19 -> 338.325
B22: CUMULATIVE GROSS CAPEX (for opex bases)
B23: Cumulative gross capex - infra (Rs cr) | D23: =D13 -> 126 | E23: =D23+E13 -> 316.8 | F23: =E23+F13 -> 568.8 | G23: =F23+G13 -> 885.6 | H23: =G23+H13 -> 1263.6
B24: Cumulative gross capex - BESS (Rs cr) | D24: =D12 -> 0.6 | E24: =D24+E12 -> 4.2 | F24: =E24+F12 -> 11.4 | G24: =F24+G12 -> 23.4 | H24: =G24+H12 -> 42
B25: Cumulative gross capex - total (Rs cr) | D25: =D23+D24 -> 126.6 | E25: =E23+E24 -> 321 | F25: =F23+F24 -> 580.2 | G25: =G23+G24 -> 909 | H25: =H23+H24 -> 1305.6
B27: DEPRECIATION (straight-line on gross capex by vintage)
B28: Depreciation - infra (Rs cr) = cum infra / life | D28: =D23/Assumptions!$G$41 -> 12.6 | E28: =E23/Assumptions!$G$41 -> 31.68 | F28: =F23/Assumptions!$G$41 -> 56.88 | G28: =G23/Assumptions!$G$41 -> 88.56 | H28: =H23/Assumptions!$G$41 -> 126.36
B29: Depreciation - BESS (Rs cr) = cum BESS / life | D29: =D24/Assumptions!$G$42 -> 0.075 | E29: =E24/Assumptions!$G$42 -> 0.525 | F29: =F24/Assumptions!$G$42 -> 1.425 | G29: =G24/Assumptions!$G$42 -> 2.925 | H29: =H24/Assumptions!$G$42 -> 5.25
B30: Total depreciation (Rs cr) | D30: =D28+D29 -> 12.675 | E30: =E28+E29 -> 32.205 | F30: =F28+F29 -> 58.305 | G30: =G28+G29 -> 91.485 | H30: =H28+H29 -> 131.61
B31: Note: Gross capex per charger = EVSE+install (Rs/lakh) + upstream (Rs/lakh); site development per site; BESS per MWh. Subsidy applies to the qualifying % of new sites at PM E-DRIVE Cat-B rates (70% EVSE / 80% upstream). Depreciation is straight-line: cumulative gross capex / useful life (10 yrs infra, 8 yrs BESS) - a simplified vintage-pool SL within the 5-year window.

Sheet Working Capital & FCF
B2: WORKING CAPITAL & UNLEVERED FREE CASH FLOW
B4: (INR crore unless stated) | D4: FY2026 | E4: FY2027 | F4: FY2028 | G4: FY2029 | H4: FY2030
B5: EBIT & TAX
B6: EBITDA (link) | D6: ='Opex & EBITDA'!D23 -> 1.2145692 | E6: ='Opex & EBITDA'!E23 -> 16.196566 | F6: ='Opex & EBITDA'!F23 -> 54.924506 | G6: ='Opex & EBITDA'!G23 -> 129.30604 | H6: ='Opex & EBITDA'!H23 -> 252.09668
B7: Depreciation (link) | D7: ='Capex & DA'!D30 -> 12.675 | E7: ='Capex & DA'!E30 -> 32.205 | F7: ='Capex & DA'!F30 -> 58.305 | G7: ='Capex & DA'!G30 -> 91.485 | H7: ='Capex & DA'!H30 -> 131.61
B8: EBIT (Rs cr) | D8: =D6-D7 -> -11.460431 | E8: =E6-E7 -> -16.008434 | F8: =F6-F7 -> -3.3804937 | G8: =G6-G7 -> 37.821042 | H8: =H6-H7 -> 120.48668
B9: Tax on EBIT (Rs cr) - taxed only if EBIT>0 | D9: =MAX(D8,0)*Assumptions!$G$40 -> 0 | E9: =MAX(E8,0)*Assumptions!$G$40 -> 0 | F9: =MAX(F8,0)*Assumptions!$G$40 -> 0 | G9: =MAX(G8,0)*Assumptions!$G$40 -> 9.5195563 | H9: =MAX(H8,0)*Assumptions!$G$40 -> 30.326498
B10: NOPAT (Rs cr) | D10: =D8-D9 -> -11.460431 | E10: =E8-E9 -> -16.008434 | F10: =F8-F9 -> -3.3804937 | G10: =G8-G9 -> 28.301486 | H10: =H8-H9 -> 90.160186
B12: WORKING CAPITAL
B13: Total revenue (link) | D13: ='Opex & EBITDA'!D8 -> 17.71491 | E13: ='Opex & EBITDA'!E8 -> 61.575704 | F13: ='Opex & EBITDA'!F8 -> 143.54513 | G13: ='Opex & EBITDA'!G8 -> 278.70282 | H13: ='Opex & EBITDA'!H8 -> 482.01918
B14: Net working capital (Rs cr) = % x revenue | D14: =D13*Assumptions!$G$39 -> 0.7085964 | E14: =E13*Assumptions!$G$39 -> 2.4630282 | F14: =F13*Assumptions!$G$39 -> 5.7418051 | G14: =G13*Assumptions!$G$39 -> 11.148113 | H14: =H13*Assumptions!$G$39 -> 19.280767
B15: Change in NWC (Rs cr) - cash outflow if +ve | D15: =D14 -> 0.7085964 | E15: =E14-D14 -> 1.7544318 | F15: =F14-E14 -> 3.2787769 | G15: =G14-F14 -> 5.4063076 | H15: =H14-G14 -> 8.1326544
B17: UNLEVERED FREE CASH FLOW
B18: Net capex (link) | D18: ='Capex & DA'!D20 -> 107.175 | E18: ='Capex & DA'!E20 -> 164.985 | F18: ='Capex & DA'!F20 -> 220.35 | G18: ='Capex & DA'!G20 -> 279.96 | H18: ='Capex & DA'!H20 -> 338.325
B19: Unlevered FCF (Rs cr) = NOPAT + Dep - Capex - dNWC | D19: =D10+D7-D18-D15 -> -106.66903 | E19: =E10+E7-E18-E15 -> -150.54287 | F19: =F10+F7-F18-F15 -> -168.70427 | G19: =G10+G7-G18-G15 -> -165.57982 | H19: =H10+H7-H18-H15 -> -124.68747
B20: Cumulative FCF (Rs cr) | D20: =D19 -> -106.66903 | E20: =D20+E19 -> -257.21189 | F20: =E20+F19 -> -425.91616 | G20: =F20+G19 -> -591.49599 | H20: =G20+H19 -> -716.18345
B21: Note: Unlevered FCF = NOPAT + Depreciation - Net capex - Increase in NWC. Tax applies only to positive EBIT (no carry-forward modelled, conservative). Subsidy already nets capex on the Capex & DA tab.

Sheet Valuation
B2: VALUATION - NPV, IRR, Payback
B4: (INR crore unless stated) | D4: FY2026 | E4: FY2027 | F4: FY2028 | G4: FY2029 | H4: FY2030
B5: PROJECT CASH FLOWS (unlevered)
B6: Discount period (yr-end, t) | D6: 1 | E6: 2 | F6: 3 | G6: 4 | H6: 5
B7: Unlevered FCF (link) | D7: ='Working Capital & FCF'!D19 -> -106.66903 | E7: ='Working Capital & FCF'!E19 -> -150.54287 | F7: ='Working Capital & FCF'!F19 -> -168.70427 | G7: ='Working Capital & FCF'!G19 -> -165.57982 | H7: ='Working Capital & FCF'!H19 -> -124.68747
B8: Discount factor = 1/(1+WACC)^t | D8: =1/(1+Assumptions!$G$43)^D6 -> 0.8988764 | E8: =1/(1+Assumptions!$G$43)^E6 -> 0.80797879 | F8: =1/(1+Assumptions!$G$43)^F6 -> 0.72627307 | G8: =1/(1+Assumptions!$G$43)^G6 -> 0.65282973 | H8: =1/(1+Assumptions!$G$43)^H6 -> 0.58681324
B9: PV of FCF (Rs cr) | D9: =D7*D8 -> -95.882272 | E9: =E7*E8 -> -121.63544 | F9: =F7*F8 -> -122.52537 | G9: =G7*G8 -> -108.09543 | H9: =H7*H8 -> -73.168257
B11: HEADLINE PROJECT VALUATION (5-yr, no terminal value)
B12: WACC (project discount rate, link) | D12: =Assumptions!$G$43 -> 0.1125
B13: NPV - 5yr build phase only, no residual (Rs cr) | D13: =SUM(D9:H9) -> -521.30677
B14: NPV incl. residual value (Rs cr) <-- HEADLINE | D14: =SUM(D9:H9)+D27 -> 139.23149
B15: Project FCF incl. residual (Rs cr) | D15: =D7 -> -106.66903 | E15: =E7 -> -150.54287 | F15: =F7 -> -168.70427 | G15: =G7 -> -165.57982 | H15: =H7+D26 -> 1000.9488
B16: IRR incl. residual value (5-yr) <-- HEADLINE | D16: =IFERROR(IRR(D15:H15),"n/m") -> 0.23857049
B17: Cumulative PV incl. residual (Rs cr) | D17: =D9 -> -95.882272 | E17: =D17+E9 -> -217.51771 | F17: =E17+F9 -> -340.04308 | G17: =F17+G9 -> -448.13851 | H17: =G17+H9+D27 -> 139.23149
B18: Discounted payback (yrs, incl. residual) | D18: =IF(H17<0,"> 5 yrs",SUMPRODUCT(--(D17:H17<0))+1) -> 5
B19: Profitability index (PV inflows incl. TV / PV outflows) | D19: =IFERROR((SUMIF(D9:H9,">0")+D27)/-SUMIF(D9:H9,"<0"),"n/m") -> 1.2670817
B20: RESIDUAL (TERMINAL) VALUE - normalized steady-state beyond FY30
B21: FY30 NOPAT (link) | D21: ='Working Capital & FCF'!H10 -> 90.160186
B22: FY30 depreciation (link) | D22: ='Working Capital & FCF'!H7 -> 131.61
B23: Steady-state maintenance capex (= depreciation) | D23: =D22 -> 131.61
B24: Terminal growth rate (g) | D24: 0.03
B25: Normalized steady-state FCF (Rs cr) | D25: =D21+D22-D23 -> 90.160186
B26: Terminal value at FY30 = FCF*(1+g)/(WACC-g) | D26: =D25*(1+D24)/(D12-D24) -> 1125.6363
B27: PV of terminal value (Rs cr) | D27: =D26*H8 -> 660.53826
B28: Note: This project is cash-flow negative during the 5-year build-out (continuous growth capex), then generates steady cash once rollout completes. As chargers/BESS have 8-10 year lives, a residual (terminal) value captures post-FY30 cash. Normalized FCF assumes maintenance capex only (no further growth capex) and stable NWC. Headline NPV/IRR (rows 14-19) include this residual value; the pure 5-year NPV (D13) is shown for transparency.

Sheet Sources
B2: SOURCES - full reference list
B4: Source | C4: Key facts used | D4: Date accessed | E4: How used in model | F4: Reliability
B5: Reliance AR FY2024-25 - Financial Performance & Review | C5: https://www.ril.com/ar2024-25/financial-performance-and-review.html | D5: 23 Jun 2026 | E5: Source Data; benchmarks SG&A/tax/NWC/WACC notes | F5: High - primary issuer disclosure
B6: Reliance Q4 FY2024-25 Media Release (PDF) | C6: https://www.ril.com/sites/default/files/2025-04/25042025_Media_Release_RIL_Q4_FY2024_25_Financial_and_Operational_Performance.pdf | D6: 23 Jun 2026 | E6: FY25 base of 701 sites / 5,750 points; incremental rollout anchor | F6: High - primary issuer disclosure
B7: Jio-bp EV Charging news page | C7: https://www.jiobp.com/news/ev-charging-news-new | D7: 23 Jun 2026 | E7: Charger architecture, fast-charging %, software opex | F7: High - first-party operator
B8: PIB - EV charging station data | C8: https://www.pib.gov.in/PressReleasePage.aspx?PRID=2204635&reg=3&lang=2 | D8: 23 Jun 2026 | E8: Market context; de-licensed regulatory basis | F8: High - Govt of India
B9: Ministry of Power - EVCI Guidelines (17 Sep 2024, PDF) | C9: https://powermin.gov.in/sites/default/files/Guidelines_and_Standards_for_EVCI_dated_17_09_2024.pdf | D9: 23 Jun 2026 | E9: Service-charge pricing ceiling, tariff pass-through, charger power, land share | F9: High - Govt of India regulation
B10: Invest India - Electric Mobility | C10: https://www.investindia.gov.in/sector/electric-mobility | D10: 23 Jun 2026 | E10: Utilization ramp justification; demand growth | F10: High - Govt investment agency
B11: NITI Aayog - e-Mobility division | C11: https://niti.gov.in/divisions/division/e-mobility | D11: 23 Jun 2026 | E11: Policy/subsidy context | F11: High - Govt think tank
B12: PIB - BESS cost & policy | C12: https://www.pib.gov.in/PressReleaseIframePage.aspx?PRID=2204118&reg=3&lang=2 | D12: 23 Jun 2026 | E12: BESS arbitrage spread, cycles, BESS capex | F12: High - Govt of India
B13: PIB - National Electricity Plan (storage) | C13: https://www.pib.gov.in/PressReleasePage.aspx?PRID=1928750 | D13: 23 Jun 2026 | E13: BESS attach growth context | F13: High - Govt of India
B14: PIB - PM E-DRIVE subsidy | C14: https://www.pib.gov.in/PressReleasePage.aspx?PRID=2200851&reg=3&lang=1 | D14: 23 Jun 2026 | E14: Subsidy rates and eligibility share | F14: High - Govt of India
B16: All assumption-tab source links point to these primary sources. Figures are as reported on access date; Reliance figures are consolidated FY2024-25. Government guidelines and PIB releases are treated as high-reliability primary regulatory sources. Where no source specifies a project-level number (e.g. per-charger capex, staffing), a clearly-flagged editable assumption is used and justified.
