Workbook

Sheet Financial Ratios
A1: TATA STEEL FINANCIAL RATIOS | G1: JSPL FINANCIAL RATIOS | M1: SAIL FINANCIAL RATIOS
A3: Ratio | B3: Mathematical formula | C3: FY2023 | D3: FY2024 | E3: FY2025 | G3: Ratio | H3: Mathematical formula | I3: FY2023 | J3: FY2024 | K3: FY2025 | M3: Ratio | N3: FY2023 | O3: FY2024 | P3: FY2025 | R3: H/L is better?
A4: Liquidity Ratio | G4: Liquidity Ratio | M4: Liquidity Ratio
A5: Current Ratio | B5: Current Assets/Current Liabilities | C5: ='Balance Sheet (TATA STEEL)'!D31/'Balance Sheet (TATA STEEL)'!D65 -> 0.78472907 | D5: ='Balance Sheet (TATA STEEL)'!E31/'Balance Sheet (TATA STEEL)'!E65 -> 0.74202777 | E5: ='Balance Sheet (TATA STEEL)'!F31/'Balance Sheet (TATA STEEL)'!F65 -> 0.6185957 | G5: Current Ratio | H5: Current Assets/Current Liabilities | I5: ='Balance Sheet (JSPL)'!D33/'Balance Sheet (JSPL)'!D67 -> 0.94216073 | J5: ='Balance Sheet (JSPL)'!E33/'Balance Sheet (JSPL)'!E67 -> 1.0776414 | K5: ='Balance Sheet (JSPL)'!F33/'Balance Sheet (JSPL)'!F67 -> 1.0435225 | M5: Current Ratio | N5: 0.54 | O5: 0.6 | P5: 0.58 | R5: higher | S5: It shows the company can cover its short-term debts with current assets.
A6: Quick ratio | B6: Quick Assets/Current Liabilities Quick Assets = Current Assets - Inventories | C6: =('Balance Sheet (TATA STEEL)'!D31-'Balance Sheet (TATA STEEL)'!D21)/'Balance Sheet (TATA STEEL)'!D65 -> 0.29198136 | D6: =('Balance Sheet (TATA STEEL)'!E31-'Balance Sheet (TATA STEEL)'!E21)/'Balance Sheet (TATA STEEL)'!E65 -> 0.2478689 | E6: =('Balance Sheet (TATA STEEL)'!F31-'Balance Sheet (TATA STEEL)'!F21)/'Balance Sheet (TATA STEEL)'!F65 -> 0.19765919 | G6: Quick ratio | H6: Quick Assets/Current Liabilities Quick Assets = Current Assets - Inventories | I6: =('Balance Sheet (JSPL)'!D33-'Balance Sheet (JSPL)'!D21)/'Balance Sheet (JSPL)'!D67 -> 0.56002412 | J6: =('Balance Sheet (JSPL)'!E33-'Balance Sheet (JSPL)'!E21)/'Balance Sheet (JSPL)'!E67 -> 0.64559104 | K6: =('Balance Sheet (JSPL)'!F33-'Balance Sheet (JSPL)'!F21)/'Balance Sheet (JSPL)'!F67 -> 0.66793656 | M6: Quick ratio | N6: 0.31 | O6: 0.38 | P6: 0.36 | R6: higher | S6: Since steel companies hold significant "Work-in-Progress" inventory that isn't easily liquidated, a strong quick ratio (excluding inventory) ensures immediate bills can be paid.
A7: Cash Ratio | B7: CCE/Current Liabilities | C7: ='Balance Sheet (TATA STEEL)'!D25/'Balance Sheet (TATA STEEL)'!D65 -> 0.023397024 | D7: ='Balance Sheet (TATA STEEL)'!E25/'Balance Sheet (TATA STEEL)'!E65 -> 0.091328813 | E7: ='Balance Sheet (TATA STEEL)'!F25/'Balance Sheet (TATA STEEL)'!F65 -> 0.057117533 | G7: Cash Ratio | H7: CCE/Current Liabilities | I7: ='Balance Sheet (JSPL)'!D26/'Balance Sheet (JSPL)'!D67 -> 0.25363856 | J7: ='Balance Sheet (JSPL)'!E26/'Balance Sheet (JSPL)'!E67 -> 0.21038254 | K7: ='Balance Sheet (JSPL)'!F26/'Balance Sheet (JSPL)'!F67 -> 0.16388378 | M7: Cash Ratio
A8: Profitability Ratio | G8: Profitability Ratio | M8: Profitability Ratio
A9: Gross Profit Margin % | B9: (Gross Profit/Net Revenue from operations)*100 | C9: =('P L Statement (TATA STEEL) '!B18/'P L Statement (TATA STEEL) '!B7)*100 -> 47.048582 | D9: =('P L Statement (TATA STEEL) '!C18/'P L Statement (TATA STEEL) '!C7)*100 -> 51.781528 | E9: =('P L Statement (TATA STEEL) '!D18/'P L Statement (TATA STEEL) '!D7)*100 -> 51.880443 | G9: Gross Profit Margin % | H9: (Gross Profit/Net Revenue from operations)*100 | I9: =('P L Statement (JSPL)'!B15/'P L Statement (JSPL)'!B4)*100 -> 32.084651 | J9: =('P L Statement (JSPL)'!C15/'P L Statement (JSPL)'!C4)*100 -> 35.786678 | K9: =('P L Statement (JSPL)'!D15/'P L Statement (JSPL)'!D4)*100 -> 33.85534 | M9: Gross Profit Margin % | N9: 2.93 | O9: 5.55 | P9: 4.85 | R9: higher
A10: Operating Profit Margin % | B10: (EBIT/Net Revenue from operations)*100 | C10: =('P L Statement (TATA STEEL) '!B67/'P L Statement (TATA STEEL) '!B7)*100 -> 17.974882 | D10: =('P L Statement (TATA STEEL) '!C67/'P L Statement (TATA STEEL) '!C7)*100 -> 21.88986 | E10: =('P L Statement (TATA STEEL) '!D67/'P L Statement (TATA STEEL) '!D7)*100 -> 20.308843 | G10: Operating Profit Margin % | H10: (EBIT/Net Revenue from operations)*100 | I10: =('P L Statement (JSPL)'!B69/'P L Statement (JSPL)'!B4)*100 -> 12.439449 | J10: =('P L Statement (JSPL)'!C69/'P L Statement (JSPL)'!C4)*100 -> 14.757224 | K10: =('P L Statement (JSPL)'!D69/'P L Statement (JSPL)'!D4)*100 -> 12.133017 | M10: Operating Profit Margin % | N10: 7.68 | O10: 10.56 | P10: 10.37 | R10: higher
A11: Net Profit Margin % | B11: (PAT/Net Revenue from operations)*100 | C11: =('P L Statement (TATA STEEL) '!B97/'P L Statement (TATA STEEL) '!B7)*100 -> 10.865992 | D11: =('P L Statement (TATA STEEL) '!C97/'P L Statement (TATA STEEL) '!C7)*100 -> 13.77861 | E11: =('P L Statement (TATA STEEL) '!D97/'P L Statement (TATA STEEL) '!D7)*100 -> 12.845985 | G11: Net Profit Margin % | H11: (PAT/Net Revenue from operations)*100 | I11: =('P L Statement (JSPL)'!B95/'P L Statement (JSPL)'!B4)*100 -> 2.6909688 | J11: =('P L Statement (JSPL)'!C95/'P L Statement (JSPL)'!C4)*100 -> 9.1249696 | K11: =('P L Statement (JSPL)'!D95/'P L Statement (JSPL)'!D4)*100 -> 5.6609003 | M11: Net Profit Margin % | N11: 1.82 | O11: 2.59 | P11: 2.09 | R11: higher
A12: ROA | B12: PAT/Total Assets | C12: ='P L Statement (TATA STEEL) '!B97/'Balance Sheet (TATA STEEL)'!D33 -> 0.063533951 | D12: ='P L Statement (TATA STEEL) '!C97/'Balance Sheet (TATA STEEL)'!E33 -> 0.078323905 | E12: ='P L Statement (TATA STEEL) '!D97/'Balance Sheet (TATA STEEL)'!F33 -> 0.066984954 | G12: ROA | H12: PAT/Total Assets | I12: ='P L Statement (JSPL)'!B95/'Balance Sheet (JSPL)'!D35 -> 0.020546734 | J12: ='P L Statement (JSPL)'!C95/'Balance Sheet (JSPL)'!E35 -> 0.062949608 | K12: ='P L Statement (JSPL)'!D95/'Balance Sheet (JSPL)'!F35 -> 0.037604822 | M12: ROA | N12: =1.49/100 -> 0.0149 | O12: =1.98/100 -> 0.0198 | P12: =1.61/100 -> 0.0161 | R12: higher | S12: It shows how well those massive blast furnaces and rolling mills are actually generating income.
A13: ROE | B13: PAT/Shareholder's Equity | C13: ='P L Statement (TATA STEEL) '!B97/'Balance Sheet (TATA STEEL)'!D38 -> 0.11171107 | D13: ='P L Statement (TATA STEEL) '!C97/'Balance Sheet (TATA STEEL)'!E38 -> 0.13749652 | E13: ='P L Statement (TATA STEEL) '!D97/'Balance Sheet (TATA STEEL)'!F38 -> 0.13432344 | G13: ROE | H13: PAT/Shareholder's Equity | I13: ='P L Statement (JSPL)'!B95/'Balance Sheet (JSPL)'!D40 -> 0.033958259 | J13: ='P L Statement (JSPL)'!C95/'Balance Sheet (JSPL)'!E40 -> 0.099650061 | K13: ='P L Statement (JSPL)'!D95/'Balance Sheet (JSPL)'!F40 -> 0.055534176 | M13: ROE | N13: =3.64/100 -> 0.0364 | O13: =5.04/100 -> 0.0504 | P13: =3.85/100 -> 0.0385 | R13: higher | S13: This measures the return for shareholders.
A14: ROCE | B14: EBIT/Capital Employed Capital Employed = Total Assets - Current Liabilities | C14: ='P L Statement (TATA STEEL) '!B67/('Balance Sheet (TATA STEEL)'!D33-'Balance Sheet (TATA STEEL)'!D65) -> 0.13334441 | D14: ='P L Statement (TATA STEEL) '!C67/('Balance Sheet (TATA STEEL)'!E33-'Balance Sheet (TATA STEEL)'!E65) -> 0.15578277 | E14: ='P L Statement (TATA STEEL) '!D67/('Balance Sheet (TATA STEEL)'!F33-'Balance Sheet (TATA STEEL)'!F65) -> 0.13479902 | G14: ROCE | H14: EBIT/Capital Employed Capital Employed = Total Assets - Current Liabilities | I14: ='P L Statement (JSPL)'!B69/('Balance Sheet (JSPL)'!D35-'Balance Sheet (JSPL)'!D67) -> 0.12073018 | J14: ='P L Statement (JSPL)'!C69/('Balance Sheet (JSPL)'!E35-'Balance Sheet (JSPL)'!E67) -> 0.12601005 | K14: ='P L Statement (JSPL)'!D69/('Balance Sheet (JSPL)'!F35-'Balance Sheet (JSPL)'!F67) -> 0.097355918 | M14: ROCE | N14: =5.67/100 -> 0.0567 | O14: =8.26/100 -> 0.0826 | P14: =7.15/100 -> 0.0715 | R14: higher | S14: In capital-heavy industries, ROCE is often considered the "gold standard" for measuring how effectively all capital (debt + equity) is being used.
A15: Turnover Ratio | G15: Turnover Ratio | M15: Turnover Ratio
A16: Inventory Turnover Ratio | B16: COGS/Average Inventories Average Inventories = (Opening Inventory + Closing Inventory)/2 | C16: ='P L Statement (TATA STEEL) '!B15/(('Balance Sheet (TATA STEEL)'!C21+'Balance Sheet (TATA STEEL)'!D21)/2) -> 3.3297632 | D16: ='P L Statement (TATA STEEL) '!C15/(('Balance Sheet (TATA STEEL)'!D21+'Balance Sheet (TATA STEEL)'!E21)/2) -> 2.709212 | E16: ='P L Statement (TATA STEEL) '!D15/(('Balance Sheet (TATA STEEL)'!E21+'Balance Sheet (TATA STEEL)'!F21)/2) -> 2.6798456 | G16: Inventory Turnover Ratio | H16: COGS/Average Inventories Average Inventories = (Opening Inventory + Closing Inventory)/2 | I16: ='P L Statement (JSPL)'!B12/(('Balance Sheet (JSPL)'!C21+'Balance Sheet (JSPL)'!D21)/2) -> 5.5554165 | J16: ='P L Statement (JSPL)'!C12/(('Balance Sheet (JSPL)'!D21+'Balance Sheet (JSPL)'!E21)/2) -> 5.5772858 | K16: ='P L Statement (JSPL)'!D12/(('Balance Sheet (JSPL)'!E21+'Balance Sheet (JSPL)'!F21)/2) -> 6.01992 | M16: Inventory Turnover Ratio | N16: 3.23 | O16: 2.83 | P16: 3.04 | R16: higher | S16: Steel is heavy and expensive to store. Faster turnover means less capital is tied up in piles of metal and raw materials.
A17: Receivables Turnover Ratio | B17: Net Revenue from operations/Average Accounts receivables Average Accounts Receivables = (Opening Accounts Receivables + Closing Accounts Receivables)/2 | C17: ='P L Statement (TATA STEEL) '!B7/(('Balance Sheet (TATA STEEL)'!C24+'Balance Sheet (TATA STEEL)'!D24)/2) -> 48.893857 | D17: ='P L Statement (TATA STEEL) '!C7/(('Balance Sheet (TATA STEEL)'!D24+'Balance Sheet (TATA STEEL)'!E24)/2) -> 67.731659 | E17: ='P L Statement (TATA STEEL) '!D7/(('Balance Sheet (TATA STEEL)'!E24+'Balance Sheet (TATA STEEL)'!F24)/2) -> 83.829124 | G17: Receivables Turnover Ratio | H17: Net Revenue from operations/Average Accounts receivables Average Accounts Receivables = (Opening Accounts Receivables + Closing Accounts Receivables)/2 | I17: ='P L Statement (JSPL)'!B4/(('Balance Sheet (JSPL)'!C25+'Balance Sheet (JSPL)'!D25)/2) -> 43.725533 | J17: ='P L Statement (JSPL)'!C4/(('Balance Sheet (JSPL)'!D25+'Balance Sheet (JSPL)'!E25)/2) -> 29.910897 | K17: ='P L Statement (JSPL)'!D4/(('Balance Sheet (JSPL)'!E25+'Balance Sheet (JSPL)'!F25)/2) -> 27.772706 | M17: Receivables Turnover Ratio | N17: 18 | O17: 24 | P17: 28 | R17: higher | S17: This indicates the company is efficient at collecting payments from its customers (construction firms, automakers, etc.).
A18: Payables Turnover Ratio | B18: COGS/Average Accounts payables Average Accounts Payables = (Opening Accounts Payables + Closing Accounts Payables)/2 | C18: ='P L Statement (TATA STEEL) '!B15/(('Balance Sheet (TATA STEEL)'!C56+'Balance Sheet (TATA STEEL)'!C57+'Balance Sheet (TATA STEEL)'!D56+'Balance Sheet (TATA STEEL)'!D57)/2) -> 3.8191561 | D18: ='P L Statement (TATA STEEL) '!C15/(('Balance Sheet (TATA STEEL)'!D56+'Balance Sheet (TATA STEEL)'!D57+'Balance Sheet (TATA STEEL)'!E56+'Balance Sheet (TATA STEEL)'!E57)/2) -> 3.5117851 | E18: ='P L Statement (TATA STEEL) '!D15/(('Balance Sheet (TATA STEEL)'!E56+'Balance Sheet (TATA STEEL)'!E57+'Balance Sheet (TATA STEEL)'!F56+'Balance Sheet (TATA STEEL)'!F57)/2) -> 3.1285114 | G18: Payables Turnover Ratio | H18: COGS/Average Accounts payables Average Accounts Payables = (Opening Accounts Payables + Closing Accounts Payables)/2 | I18: ='P L Statement (JSPL)'!B12/(('Balance Sheet (JSPL)'!C58+'Balance Sheet (JSPL)'!C59+'Balance Sheet (JSPL)'!D58+'Balance Sheet (JSPL)'!D59)/2) -> 7.1293614 | J18: ='P L Statement (JSPL)'!C12/(('Balance Sheet (JSPL)'!D58+'Balance Sheet (JSPL)'!D59+'Balance Sheet (JSPL)'!E58+'Balance Sheet (JSPL)'!E59)/2) -> 7.3085608 | K18: ='P L Statement (JSPL)'!D12/(('Balance Sheet (JSPL)'!E58+'Balance Sheet (JSPL)'!E59+'Balance Sheet (JSPL)'!F58+'Balance Sheet (JSPL)'!F59)/2) -> 6.9084004 | M18: Payables Turnover Ratio | N18: 20.68 | O18: 15.42 | P18: 12.92 | R18: lower | S18: This suggests the company is effectively using "interest-free" credit from its suppliers, though it must be careful not to damage supplier relationships.
A19: Asset Turnover Ratio | B19: Net Revenue from operations/Total Assets | C19: ='P L Statement (TATA STEEL) '!B7/'Balance Sheet (TATA STEEL)'!D33 -> 0.58470456 | D19: ='P L Statement (TATA STEEL) '!C7/'Balance Sheet (TATA STEEL)'!E33 -> 0.56844563 | E19: ='P L Statement (TATA STEEL) '!D7/'Balance Sheet (TATA STEEL)'!F33 -> 0.52144663 | G19: Asset Turnover Ratio | H19: Net Revenue from operations/Total Assets | I19: ='P L Statement (JSPL)'!B4/'Balance Sheet (JSPL)'!D35 -> 0.76354412 | J19: ='P L Statement (JSPL)'!C4/'Balance Sheet (JSPL)'!E35 -> 0.68986101 | K19: ='P L Statement (JSPL)'!D4/'Balance Sheet (JSPL)'!F35 -> 0.66429048 | M19: Asset Turnover Ratio | N19: 0.84 | O19: 0.82 | P19: 0.77 | R19: higher | S19: This reflects how much revenue is generated for every dollar invested in the steel plant and equipment.
A20: Fixed Asset Turnover Ratio | B20: Net Revenue from operations/Fixed Assets | C20: ='P L Statement (TATA STEEL) '!B7/'Balance Sheet (TATA STEEL)'!D6 -> 1.5545061 | D20: ='P L Statement (TATA STEEL) '!C7/'Balance Sheet (TATA STEEL)'!E6 -> 1.5259341 | E20: ='P L Statement (TATA STEEL) '!D7/'Balance Sheet (TATA STEEL)'!F6 -> 1.4217941 | G20: Fixed Asset Turnover Ratio | H20: Net Revenue from operations/Fixed Assets | I20: ='P L Statement (JSPL)'!B4/'Balance Sheet (JSPL)'!D6 -> 1.2953227 | J20: ='P L Statement (JSPL)'!C4/'Balance Sheet (JSPL)'!E6 -> 1.2865157 | K20: ='P L Statement (JSPL)'!D4/'Balance Sheet (JSPL)'!F6 -> 1.2549464 | M20: Fixed Asset Turnover Ratio | N20: 1.46 | O20: 1.3 | P20: 1.2
A21: W/C Turnover Ratio | B21: Net Revenue from operations/Net W/C Net W/C = Current Assets - Current Liabilities | C21: ='P L Statement (TATA STEEL) '!B7/('Balance Sheet (TATA STEEL)'!D31-'Balance Sheet (TATA STEEL)'!D65) -> -12.823088 | D21: ='P L Statement (TATA STEEL) '!C7/('Balance Sheet (TATA STEEL)'!E31-'Balance Sheet (TATA STEEL)'!E65) -> -10.949304 | E21: ='P L Statement (TATA STEEL) '!D7/('Balance Sheet (TATA STEEL)'!F31-'Balance Sheet (TATA STEEL)'!F65) -> -6.377119 | G21: W/C Turnover Ratio | H21: Net Revenue from operations/Net W/C Net W/C = Current Assets - Current Liabilities | I21: ='P L Statement (JSPL)'!B4/('Balance Sheet (JSPL)'!D33-'Balance Sheet (JSPL)'!D67) -> -61.895414 | J21: ='P L Statement (JSPL)'!C4/('Balance Sheet (JSPL)'!E33-'Balance Sheet (JSPL)'!E67) -> 46.25469 | K21: ='P L Statement (JSPL)'!D4/('Balance Sheet (JSPL)'!F33-'Balance Sheet (JSPL)'!F67) -> 88.674604 | M21: W/C Turnover Ratio
A22: Capital Turnover Ratio | B22: Net Revenue from operations/Capital Employed Capital Employed = Total Assets - Current Liabilities | C22: ='P L Statement (TATA STEEL) '!B7/('Balance Sheet (TATA STEEL)'!D33-'Balance Sheet (TATA STEEL)'!D65) -> 0.74183751 | D22: ='P L Statement (TATA STEEL) '!C7/('Balance Sheet (TATA STEEL)'!E33-'Balance Sheet (TATA STEEL)'!E65) -> 0.71166637 | E22: ='P L Statement (TATA STEEL) '!D7/('Balance Sheet (TATA STEEL)'!F33-'Balance Sheet (TATA STEEL)'!F65) -> 0.66374545 | G22: Capital Turnover Ratio | H22: Net Revenue from operations/Capital Employed Capital Employed = Total Assets - Current Liabilities | I22: ='P L Statement (JSPL)'!B4/('Balance Sheet (JSPL)'!D35-'Balance Sheet (JSPL)'!D67) -> 0.9705428 | J22: ='P L Statement (JSPL)'!C4/('Balance Sheet (JSPL)'!E35-'Balance Sheet (JSPL)'!E67) -> 0.85388717 | K22: ='P L Statement (JSPL)'!D4/('Balance Sheet (JSPL)'!F35-'Balance Sheet (JSPL)'!F67) -> 0.80240485 | M22: Capital Turnover Ratio
A23: Solvency Ratio | G23: Solvency Ratio | M23: Solvency Ratio
A24: Debt Ratio | B24: Total Liabilities/Total Assets | C24: ='Balance Sheet (TATA STEEL)'!D66/'Balance Sheet (TATA STEEL)'!D33 -> 0.43126538 | D24: ='Balance Sheet (TATA STEEL)'!E66/'Balance Sheet (TATA STEEL)'!E33 -> 0.43035716 | E24: ='Balance Sheet (TATA STEEL)'!F66/'Balance Sheet (TATA STEEL)'!F33 -> 0.50131597 | G24: Debt Ratio | H24: Total Liabilities/Total Assets | I24: ='Balance Sheet (JSPL)'!D68/'Balance Sheet (JSPL)'!D35 -> 0.39494146 | J24: ='Balance Sheet (JSPL)'!E68/'Balance Sheet (JSPL)'!E35 -> 0.36829333 | K24: ='Balance Sheet (JSPL)'!F68/'Balance Sheet (JSPL)'!F35 -> 0.32285262 | M24: Debt Ratio
A25: Debt-to-equity Ratio | B25: Total Liabilities/Shareholder's Equity | C25: ='Balance Sheet (TATA STEEL)'!D66/'Balance Sheet (TATA STEEL)'!D38 -> 0.75828932 | D25: ='Balance Sheet (TATA STEEL)'!E66/'Balance Sheet (TATA STEEL)'!E38 -> 0.75548595 | E25: ='Balance Sheet (TATA STEEL)'!F66/'Balance Sheet (TATA STEEL)'!F38 -> 1.0052778 | G25: Debt-to-equity Ratio | H25: Total Liabilities/Shareholder's Equity | I25: ='Balance Sheet (JSPL)'!D68/'Balance Sheet (JSPL)'!D40 -> 0.65273265 | J25: ='Balance Sheet (JSPL)'!E68/'Balance Sheet (JSPL)'!E40 -> 0.58301322 | K25: ='Balance Sheet (JSPL)'!F68/'Balance Sheet (JSPL)'!F40 -> 0.47678339 | M25: Debt-to-equity Ratio | N25: 0.49 | O25: 0.57 | P25: 0.54 | R25: Lower | S25: High leverage in a cyclical industry is risky; if steel prices drop, a highly indebted company may struggle.
A26: Debt-to-(debt+shareholder's equity) Ratio | B26: Total Liabilities/(Total Liabilities+Total Shareholder's Equity) | C26: ='Balance Sheet (TATA STEEL)'!D66/'Balance Sheet (TATA STEEL)'!D67 -> 0.43126538 | D26: ='Balance Sheet (TATA STEEL)'!E66/'Balance Sheet (TATA STEEL)'!E67 -> 0.43035716 | E26: ='Balance Sheet (TATA STEEL)'!F66/'Balance Sheet (TATA STEEL)'!F67 -> 0.50131597 | G26: Debt-to-(debt+shareholder's equity) Ratio | H26: Total Liabilities/(Total Liabilities+Total Shareholder's Equity) | I26: ='Balance Sheet (JSPL)'!D68/'Balance Sheet (JSPL)'!D69 -> 0.39494146 | J26: ='Balance Sheet (JSPL)'!E68/'Balance Sheet (JSPL)'!E69 -> 0.36829333 | K26: ='Balance Sheet (JSPL)'!F68/'Balance Sheet (JSPL)'!F69 -> 0.32285262 | M26: Debt-to-(debt+shareholder's equity) Ratio
A27: Interest Coverage Ratio | B27: EBIT/Interest expense | C27: ='P L Statement (TATA STEEL) '!B67/'P L Statement (TATA STEEL) '!B73 -> 6.4631173 | D27: ='P L Statement (TATA STEEL) '!C67/'P L Statement (TATA STEEL) '!C73 -> 7.5234263 | E27: ='P L Statement (TATA STEEL) '!D67/'P L Statement (TATA STEEL) '!D73 -> 6.3497823 | G27: Interest Coverage Ratio | H27: EBIT/Interest expense | I27: ='P L Statement (JSPL)'!B69/'P L Statement (JSPL)'!B78 -> 4.9514847 | J27: ='P L Statement (JSPL)'!C69/'P L Statement (JSPL)'!C78 -> 7.9622502 | K27: ='P L Statement (JSPL)'!D69/'P L Statement (JSPL)'!D78 -> 9.5530789 | M27: Interest Coverage Ratio | N27: 2.17 | O27: 2.83 | P27: 2.19 | R27: Higher | S27: This indicates how many times the company can pay its interest expenses out of its operating profits.
A28: Equity ratio | B28: Shareholder's Equity/Total Assets | C28: ='Balance Sheet (TATA STEEL)'!D38/'Balance Sheet (TATA STEEL)'!D33 -> 0.56873462 | D28: ='Balance Sheet (TATA STEEL)'!E38/'Balance Sheet (TATA STEEL)'!E33 -> 0.56964284 | E28: ='Balance Sheet (TATA STEEL)'!F38/'Balance Sheet (TATA STEEL)'!F33 -> 0.49868403 | G28: Equity ratio | H28: Shareholder's Equity/Total Assets | I28: ='Balance Sheet (JSPL)'!D40/'Balance Sheet (JSPL)'!D35 -> 0.60505854 | J28: ='Balance Sheet (JSPL)'!E40/'Balance Sheet (JSPL)'!E35 -> 0.63170667 | K28: ='Balance Sheet (JSPL)'!F40/'Balance Sheet (JSPL)'!F35 -> 0.67714738 | M28: Equity ratio
A29: Debt Service Coverage Ratio | B29: EBIT/Total Debt Service Total Debt Service = Principal Repayment + Interest Expense Principal Repayment = current maturities of long-term borrowings | C29: ='P L Statement (TATA STEEL) '!B67/('P L Statement (TATA STEEL) '!B73+'Balance Sheet (TATA STEEL)'!D97+'Balance Sheet (TATA STEEL)'!D102) -> 2.501485 | D29: ='P L Statement (TATA STEEL) '!C67/('P L Statement (TATA STEEL) '!C73+'Balance Sheet (TATA STEEL)'!E97+'Balance Sheet (TATA STEEL)'!E102) -> 3.8843874 | E29: ='P L Statement (TATA STEEL) '!D67/('P L Statement (TATA STEEL) '!D73+'Balance Sheet (TATA STEEL)'!F97+'Balance Sheet (TATA STEEL)'!F102) -> 2.8918037 | G29: Debt Service Coverage Ratio | H29: EBIT/Total Debt Service Total Debt Service = Principal Repayment + Interest Expense Principal Repayment = current maturities of long-term borrowings | I29: ='P L Statement (JSPL)'!B69/('P L Statement (JSPL)'!B78+'Balance Sheet (JSPL)'!D101) -> 1.3771583 | J29: ='P L Statement (JSPL)'!C69/('P L Statement (JSPL)'!C78+'Balance Sheet (JSPL)'!E101+'Balance Sheet (JSPL)'!E106) -> 2.2347996 | K29: ='P L Statement (JSPL)'!D69/('P L Statement (JSPL)'!D78+'Balance Sheet (JSPL)'!F101+'Balance Sheet (JSPL)'!F106) -> 2.880535 | M29: Debt Service Coverage Ratio | N29: 2.66 | O29: 2.08 | P29: 2.68 | R29: Higher | S29: This is a critical metric for banks, showing the company's ability to cover both principal and interest payments.

Sheet FP Analysis 
A1: (as per 2025 ratios) | B1: Current | C1: Quick | D1: Gross Profit | E1: Operating Profit | F1: Net Profit | G1: ROA | H1: ROE | I1: ROCE | J1: Inventory | K1: Receivables | L1: Payables | M1: Asset | N1: D/E | O1: ICR | P1: DSCR
A2: 1 | B2: JSPL | C2: JSPL | D2: Tata | E2: Tata | F2: Tata | G2: Tata | H2: Tata | I2: Tata | J2: JSPL | K2: Tata | L2: Tata | M2: SAIL | N2: JSPL | O2: JSPL | P2: Tata
A3: 2 | B3: Tata | C3: SAIL | D3: JSPL | E3: JSPL | F3: JSPL | G3: JSPL | H3: JSPL | I3: JSPL | J3: SAIL | K3: JSPL | L3: JSPL | M3: JSPL | N3: Tata | O3: Tata | P3: JSPL
A4: 3 | B4: SAIL | C4: Tata | D4: SAIL | E4: SAIL | F4: SAIL | G4: SAIL | H4: SAIL | I4: SAIL | J4: Tata | K4: SAIL | L4: SAIL | M4: Tata | N4: SAIL | O4: SAIL | P4: SAIL
A6: H/L? | B6: higher | C6: higher | D6: higher | E6: higher | F6: higher | G6: higher | H6: higher | I6: higher | J6: higher | K6: higher | L6: lower | M6: higher | N6: lower | O6: higher | P6: higher
B8: 9/15 ratios | C8: Tata Steel has performed better than its chosen peers
B9: 3/15 ratios | C9: Decent performances with room for improvement
B10: 3/15 ratios | C10: Indicative of specific factors to be looked into - variance and reasons
A12: Current | B12: decreasing - lower ca or higher cl? | C12: CA decreasing by 9% yoy - inventories, investments, loans; accompanied by a slight increase in CL mainy due to trade payables
A13: Quick | B13: decreasing - lower qa or higher cl? | C13: Inventories account for 60 to 68% of CA, locking up most CA in stock; accompanied by a slight increase in CL mainy due to trade payables
A15: Gross Profit | B15: increasing - higher gp (higher rev or lower cogs) or lower rev from ops | C15: higher GP due to lower COGS, reduced revenue from operations | K15: GP margin advantage flows down to the operating and net profit level
A16: Operating Profit | B16: increasing - higher EBIT (higher rev or lower cogs/sga/da) or lower rev from ops | C16: consistent decrease in revenue coupled with lower COGS as compared to SGA/DA
A17: Net Profit | B17: increasing - higher np (higher rev or lower exp) or lower rev from ops | C17: consistent decrease in revenue coupled with lower COGS as compared to SGA/DA/Exceptional Items/Finance Cost
A18: ROA | B18: increasing - higher np (higher rev or lower exp) or lower assets | C18: mainly impacted by reduced COGS as revenue was declining and assets were increasing
A19: ROE | B19: increase then decrease - PAT and Equity | C19: PAT (25%) increased more than Equity (1.6%), hence the increase; PAT (12%) decreased more than equity (10%), hence the decrease
A20: ROCE | B20: increase then decrease - EBIT (rev from ops, cogs, sga, da) and fixed assets (total asset - cl) | C20: increase - increase in EBIT mainly due to decrease in COGS (10%) despite increase in FA (3.5%); decrease - lower EBIT coupled with further increase in FA
A22: Inventory | B22: decreasing - lower cogs or increasing inventories | C22: lower COGS
A23: Receivables | B23: increasing - increasing net rev from ops or lower receivables | C23: lower receivables
A24: Payables | B24: decreasing - lower cogs or increasing payables | C24: lower COGS AND increasing payables
A25: Asset | B25: decreasing - lower rev from ops or higher total assets | C25: (more of) lower rev from ops AND higher total assets
A27: D/E | B27: stable then increase - higher liabilities or lower equity | C27: equity decreased AND total liabilities increased causing the increase
A28: ICR | B28: increase then decrease - EBIT (rev from ops, cogs, sga, da) and total assets
A29: DSCR | B29: increase then decrease - EBIT (rev from ops, cogs, sga, da) and principal repayment/interest
B31: Liquidity - Not the best, also has been decreasing
B32: The culprit is the Kalinganagar Phase 2 expansion — Tata Steel has borrowed aggressively, pushing non-current borrowings up by ~₹14,325 Cr in FY25 alone. This simultaneously inflates current liabilities (commercial paper, current maturities), swells inventory (steel inputs), and reduces free cash.
B33: Solvency - Decent position when compared with peers despite decrease in coverage ratios. The D/E crossing 1.0× for the first time is a key flag
B34: Profitability - Outperforming chosen peers while providing increasing margins and returns. This is fundamentally driven by its captive iron ore mines (Noamundi, Joda) and high-value product mix (automotive-grade flat steel), which compress COGS and protect margins even when HRC prices fall.
B35: Turnover - Considering lower COGS is due to decrease in prices rather than volume which has led to decrease in Inventory Turnover Ratio, cannot say decrease is a 100% negative indicator, can look into why/how JSPL is performing better
B36: Asset Turnover ratio also to be taken with caution as revenue was lower due to realisable value despite higher deliveries, also new assets introduced in kalinganagar expansion yet to yield results as they just started operations
B39: it's in a heavy investment phase — CAPEX work-in-progress nearly tripled from FY2022 to FY2025 (₹14,159 cr to ₹34,189 cr), funded by a sharp rise in long-term debt.
B40: This explains almost every "declining" ratio: weaker liquidity, higher D/E, falling asset turnover, dipping ROCE. These are not signs of a struggling company — they're the fingerprints of a company investing aggressively for future growth.

Sheet SAIL
B1: Mar '25 | C1: Mar '24 | D1: Mar '23 | E1: Mar '22 | F1: Mar '21
A3: Investment Valuation Ratios | G3: https://www.moneycontrol.com/financials/steelauthorityindia/ratiosVI/sai#sai
A4: Face Value | B4: 10 | C4: 10 | D4: 10 | E4: 10 | F4: 10
A5: Dividend Per Share | B5: 1.6 | C5: 2 | D5: 1.5 | E5: 8.75 | F5: 2.8
A6: Operating Profit Per Share (Rs) | B6: 25.73 | C6: 26.95 | D6: 19.43 | E6: 51.62 | F6: 30.81
A7: Net Operating Profit Per Share (Rs) | B7: 248.1 | C7: 255.11 | D7: 252.87 | E7: 250.51 | F7: 167.32
A8: Free Reserves Per Share (Rs) | B8: -- | C8: -- | D8: -- | E8: -- | F8: --
A9: Bonus in Equity Capital | B9: -- | C9: -- | D9: -- | E9: -- | F9: --
A10: Profitability Ratios
A11: Operating Profit Margin(%) | B11: 10.37 | C11: 10.56 | D11: 7.68 | E11: 20.6 | F11: 18.41
A12: Profit Before Interest And Tax Margin(%) | B12: 4.8 | C12: 5.49 | D12: 2.89 | E12: 16.31 | F12: 12.3
A13: Gross Profit Margin(%) | B13: 4.85 | C13: 5.55 | D13: 2.93 | E13: 16.47 | F13: 12.48
A14: Cash Profit Margin(%) | B14: 7.82 | C14: 8.3 | D14: 6.24 | E14: 15.92 | F14: 11.25
A15: Adjusted Cash Margin(%) | B15: 7.82 | C15: 8.3 | D15: 6.24 | E15: 15.92 | F15: 11.25
A16: Net Profit Margin(%) | B16: 2.09 | C16: 2.59 | D16: 1.82 | E16: 11.61 | F16: 5.57
A17: Adjusted Net Profit Margin(%) | B17: 2.07 | C17: 2.56 | D17: 1.79 | E17: 11.49 | F17: 5.49
A18: Return On Capital Employed(%) | B18: 7.15 | C18: 8.26 | D18: 5.67 | E18: 27.65 | F18: 12.18
A19: Return On Net Worth(%) | B19: 3.85 | C19: 5.04 | D19: 3.64 | E19: 23.09 | F19: 8.85
A20: Adjusted Return on Net Worth(%) | B20: 4.42 | C20: 6.6 | D20: 3.15 | E20: 23.77 | F20: 8.71
A21: Return on Assets Excluding Revaluations | B21: 134.74 | C21: 131.05 | D21: 126.23 | E21: 125.93 | F21: 105.3
A22: Return on Assets Including Revaluations | B22: 134.74 | C22: 131.05 | D22: 126.23 | E22: 125.93 | F22: 105.3
A23: Return on Long Term Funds(%) | B23: 9.29 | C23: 10.99 | D23: 7.58 | E23: 30.07 | F23: 15.24
A24: Liquidity And Solvency Ratios
A25: Current Ratio | B25: 0.58 | C25: 0.6 | D25: 0.54 | E25: 0.61 | F25: 0.56
A26: Quick Ratio | B26: 0.36 | C26: 0.38 | D26: 0.31 | E26: 0.27 | F26: 0.51
A27: Debt Equity Ratio | B27: 0.54 | C27: 0.57 | D27: 0.49 | E27: 0.26 | F27: 0.82
A28: Long Term Debt Equity Ratio | B28: 0.18 | C28: 0.18 | D28: 0.12 | E28: 0.16 | F28: 0.45
A29: Debt Coverage Ratios
A30: Interest Cover | B30: 2.19 | C30: 2.83 | D30: 2.17 | E30: 10.65 | F30: 3.42
A31: Total Debt to Owners Fund | B31: 0.54 | C31: 0.57 | D31: 0.49 | E31: 0.26 | F31: 0.82
A32: Financial Charges Coverage Ratio | B32: 4.21 | C32: 4.96 | D32: 4.6 | E32: 13.17 | F32: 4.88
A33: Financial Charges Coverage Ratio Post Tax | B33: 3.79 | C33: 4.24 | D33: 4.37 | E33: 10.59 | F33: 3.82
A34: Management Efficiency Ratios
A35: Inventory Turnover Ratio | B35: 3.04 | C35: 2.83 | D35: 3.23 | E35: 4.29 | F35: 3.54
A36: Debtors Turnover Ratio | B36: 12.92 | C36: 15.42 | D36: 20.68 | E36: 17.45 | F36: 8.67
A37: Investments Turnover Ratio | B37: 1.2 | C37: 1.24 | D37: 1.34 | E37: 1.58 | F37: 0.87
A38: Fixed Assets Turnover Ratio | B38: 0.77 | C38: 0.82 | D38: 0.84 | E38: 0.86 | F38: 0.62
A39: Total Assets Turnover Ratio | B39: 1.22 | C39: 1.27 | D39: 1.37 | E39: 1.62 | F39: 0.89
A40: Asset Turnover Ratio | B40: 1.2 | C40: 1.3 | D40: 1.46 | E40: 1.43 | F40: 0.81
A42: Average Raw Material Holding | B42: -- | C42: -- | D42: -- | E42: -- | F42: --
...

Sheet Balance Sheet (JSPL)
A1: JSPL BALANCE SHEET ANALYSIS
A3: Ref | B3: Particulars | C3: FY2022 | D3: FY2023 | E3: FY2024 | F3: FY2025
A4: Assets
A5: I | B5: Non-current assets
A6: (a) | B6: Property, plant and equipment | C6: 40975.99 | D6: 39511.45 | E6: 38617.25 | F6: 38900.49
A7: (b) | B7: Capital work-in-progress | C7: 731.43 | D7: 2090.58 | E7: 3780.05 | F7: 5009.78
A8: (c) | B8: Right-of-use assets | C8: 0 | D8: 0 | E8: 0 | F8: 0
A9: (d) | B9: Goodwill | C9: 0 | D9: 0 | E9: 0 | F9: 0
A10: (e) | B10: Other intangible assets | C10: 382.27 | D10: 572.04 | E10: 855.78 | F10: 936.82
A11: (f) | B11: Intangible assets under development | C11: 28.15 | D11: 28.15 | E11: 22.16 | F11: 464.98
A12: (g) | B12: Financial assets
A13: (i) | B13: Investments | C13: 2041.47 | D13: 4931.55 | E13: 6892.17 | F13: 8554.51
A14: (ii) | B14: Loans | C14: 7842.35 | D14: 5446.69 | E14: 5523.34 | F14: 5162.01
A15: (iii) | B15: Derivative assets | C15: 0 | D15: 0 | E15: 0 | F15: 0
A16: (iv) | B16: Other financial assets | C16: 1033.21 | D16: 426.57 | E16: 797.91 | F16: 672.16
A17: (h) | B17: Non-current tax assets (net) | C17: 0 | D17: 0 | E17: 0 | F17: 0
A18: (i) | B18: Other assets | C18: 399.11 | D18: 538.77 | E18: 607.95 | F18: 575.94
B19: Total non-current assets | C19: =SUM(C6:C18) -> 53433.98 | D19: =SUM(D6:D18) -> 53545.8 | E19: =SUM(E6:E18) -> 57096.61 | F19: =SUM(F6:F18) -> 60276.69
A20: II | B20: Current assets
A21: (a) | B21: Inventories | C21: 7050.51 | D21: 5463.09 | E21: 5976.98 | F21: 4750.91
A22: (b) | B22: Investments in Subsidiaries (held for sale) | C22: 3947.09 | D22: 0 | E22: 0 | F22: 0
A23: (c) | B23: Financial assets
A24: (i) | B24: Investments | C24: 327.42 | D24: 761.13 | E24: 638.7 | F24: 1314.83
A25: (ii) | B25: Trade receivables | C25: 1210.47 | D25: 1130.5 | E25: 2191.48 | F25: 1324.06
A26: (iii) | B26: Cash and cash equivalents | C26: 2903.29 | D26: 3626.06 | E26: 2910.43 | F26: 2073.02
A27: (iv) | B27: Other balances with banks | C27: 152.53 | D27: 396.9 | E27: 579.02 | F27: 1491.63
A28: (v) | B28: Loans | C28: 3973.7 | D28: 50.19 | E28: 26.06 | F28: 46.46
A29: (vi) | B29: Derivative assets | C29: 0 | D29: 0 | E29: 0 | F29: 0
A30: (vii) | B30: Other financial assets | C30: 459.26 | D30: 476.12 | E30: 146.3 | F30: 271.25
A31: (d) | B31: Current tax assets (net) | C31: 0 | D31: 0 | E31: 155.01 | F31: 37.3
A32: (d) | B32: Other assets | C32: 1684.86 | D32: 1565.3 | E32: 2284.1 | F32: 1890.4
B33: Total current assets | C33: =SUM(C21:C32) -> 21709.13 | D33: =SUM(D21:D32) -> 13469.29 | E33: =SUM(E21:E32) -> 14908.08 | F33: =SUM(F21:F32) -> 13199.86
A34: III | B34: Assets held for sale | C34: 19.14 | D34: 14.54 | E34: 12.28 | F34: 12.43
A35: Total assets | C35: =C19+C33+C34 -> 75162.25 | D35: =D19+D33+D34 -> 67029.63 | E35: =E19+E33+E34 -> 72016.97 | F35: =F19+F33+F34 -> 73488.98
A36: Equity and liabilities
A37: IV | B37: Equity
A38: (a) | B38: Equity share capital | C38: 101.07 | D38: 100.5 | E38: 100.24 | F38: 101.18
A39: (b) | B39: Other equity | C39: 40259.41 | D39: 40456.35 | E39: 45393.36 | F39: 49661.69
B40: Total equity | C40: =SUM(C38:C39) -> 40360.48 | D40: =SUM(D38:D39) -> 40556.85 | E40: =SUM(E38:E39) -> 45493.6 | F40: =SUM(F38:F39) -> 49762.87
A41: V | B41: Non-current liabilities
...

Sheet P L Statement (JSPL)
A1: JSPL P/L STATEMENT ANALYSIS
A3: Particulars | B3: FY2023 | C3: FY2024 | D3: FY2025
A4: Revenue from operations | B4: 51180.08 | C4: 49681.7 | D4: 48818.03
A5: % Change | C5: =(C4/B4-1)*100 -> -2.9276625 | D5: =(D4/C4-1)*100 -> -1.7384067
A7: Cost of materials consumed | B7: 22643.82 | C7: 21390.88 | D7: 23034.67
A8: Power, fuel and industrial gases | B8: 9025.62 | C8: 6576.02 | D8: 5312.91
A9: Other manufacturing expenses | B9: 1352.7 | C9: 1541.64 | D9: 1652.9
A10: Purchases of SIT | B10: 1782.02 | C10: 2251.49 | D10: 1762.84
A11: Changes in inventories (finished/semi-finished/SIT/WIP) | B11: -45.03 | C11: 142.24 | D11: 527.2
A12: COGS | B12: =SUM(B7:B11) -> 34759.13 | C12: =SUM(C7:C11) -> 31902.27 | D12: =SUM(D7:D11) -> 32290.52
A13: % Change | C13: =(C12/B12-1)*100 -> -8.2190204 | D13: =(D12/C12-1)*100 -> 1.216998
A15: Gross Profit | B15: =B4-B12 -> 16420.95 | C15: =C4-C12 -> 17779.43 | D15: =D4-D12 -> 16527.51
A16: % Gross Margin | B16: =(B15/B4)*100 -> 32.084651 | C16: =(C15/C4)*100 -> 35.786678 | D16: =(D15/D4)*100 -> 33.85534
A17: % Change (for Gross Profit) | C17: =(C15/B15-1)*100 -> 8.2728466 | D17: =(D15/C15-1)*100 -> -7.0413956
A19: Freight and handling charges | B19: 1955.93 | C19: 1487.18 | D19: 1446.58
A20: Bad debts & Sundry balances written off | B20: 0 | C20: 17.45 | D20: 53.87
A21: Less: Loss Allowances no longer required written back | B21: 0 | C21: 0 | D21: 0
A22: Loss Allowances for Trade & Other Receivables (net) | B22: 3.92 | C22: 14.43 | D22: 24.37
A23: Selling and marketing expenses | B23: =SUM(B19:B22) -> 1959.85 | C23: =SUM(C19:C22) -> 1519.06 | D23: =SUM(D19:D22) -> 1524.82
A24: % Change | C24: =(C23/B23-1)*100 -> -22.491007 | D24: =(D23/C23-1)*100 -> 0.37918186
A26: Consumption of stores and spares | B26: 3978.73 | C26: 3780.14 | D26: 3519.32
A27: Repairs to plant and machinery | B27: 261.43 | C27: 294.5 | D27: 489.98
A28: Repairs to building | B28: 36.85 | C28: 24.49 | D28: 23.18
A29: Other repairs | B29: 62.24 | C29: 101.57 | D29: 153.75
A30: Rent | B30: 12.77 | C30: 10.33 | D30: 11.11
A31: PPE / CWIP discarded / Written Off | B31: 4.17 | C31: 41.06 | D31: 22.99
A32: Loss on sale of PPE | B32: 0.41 | C32: 0.91 | D32: 0.8
A33: Donation | B33: 38 | C33: 102.12 | D33: 100.31
A34: Corporate Social Responsibility Expense | B34: 236.3 | C34: 225.93 | D34: 267.42
A35: Loan & Interest Receivables written Off | B35: 0 | C35: 7776.51 | D35: 0
A36: Less: Loss Allowances on loan & Interest receivables no longer required written back | B36: 0 | C36: -7776.51 | D36: 0
A37: Investments written off | B37: 0 | C37: 0.2 | D37: 102
A38: Foreign exchange fluctuation (net) | B38: -889.89 | C38: -164.65 | D38: -152.97
A39: General expenses | B39: =SUM(B26:B38) -> 3741.01 | C39: =SUM(C26:C38) -> 4416.6 | D39: =SUM(D26:D38) -> 4537.89
A40: % Change | C40: =(C39/B39-1)*100 -> 18.059027 | D40: =(D39/C39-1)*100 -> 2.7462301
A42: Salaries and wages | B42: 769.64 | C42: 816.59 | D42: 806.46
A43: Contribution to PF and other funds | B43: 56.81 | C43: 62.34 | D43: 90.7
A44: Staff welfare expenses | B44: 47.76 | C44: 44.92 | D44: 75.48
A45: Tax and rates | B45: 29.37 | C45: 116.61 | D45: 64.75
A46: Insurance | B46: 95.28 | C46: 68.54 | D46: 73.2
...

Sheet Balance Sheet (TATA STEEL)
A1: TATA STEEL BALANCE SHEET ANALYSIS
A3: Ref | B3: Particulars | C3: FY2022 | D3: FY2023 | E3: FY2024 | F3: FY2025
A4: Assets
A5: I | B5: Non-current assets
A6: (a) | B6: Property, plant and equipment | C6: 87946.22 | D6: 91934.87 | E6: 92358.28 | F6: 93203.83
A7: (b) | B7: Capital work-in-progress | C7: 14159.32 | D7: 21677.96 | E7: 27562.62 | F7: 34189.06
A8: (c) | B8: Right-of-use assets | C8: 5538.18 | D8: 5297.33 | E8: 5066.37 | F8: 5342.89
A9: (d) | B9: Goodwill | C9: 0 | D9: 12.66 | E9: 12.66 | F9: 12.66
A10: (e) | B10: Other intangible assets | C10: 806.03 | D10: 1234.14 | E10: 968.2 | F10: 919.68
A11: (f) | B11: Intangible assets under development | C11: 382.64 | D11: 514.96 | E11: 532.59 | F11: 671.24
A12: (g) | B12: Financial assets
A13: (i) | B13: Investments | C13: 43401.43 | D13: 40288.44 | E13: 66240 | F13: 72699.01
A14: (ii) | B14: Loans | C14: 30195.27 | D14: 32275.99 | E14: 8436.03 | F14: 4816.22
A15: (iii) | B15: Derivative assets | C15: 133.21 | D15: 403.4 | E15: 265.81 | F15: 0
A16: (iv) | B16: Other financial assets | C16: 1211.81 | D16: 2293.3 | E16: 1626.03 | F16: 2015.58
A17: (h) | B17: Non-current tax assets (net) | C17: 3620.76 | D17: 4312.42 | E17: 4705.34 | F17: 3763.2
A18: (i) | B18: Other assets | C18: 3301.78 | D18: 3539.04 | E18: 3129.36 | F18: 2796.47
B19: Total non-current assets | C19: =SUM(C6:C18) -> 190696.65 | D19: =SUM(D6:D18) -> 203784.51 | E19: =SUM(E6:E18) -> 210903.29 | F19: =SUM(F6:F18) -> 220429.84
A20: II | B20: Current assets
A21: (a) | B21: Inventories | C21: 19942.94 | D21: 25510.52 | E21: 24655.78 | F21: 22933.85
A22: (b) | B22: Financial assets
A23: (i) | B23: Investments | C23: 96.11 | D23: 2994.48 | E23: 585.6 | F23: 0.12
A24: (ii) | B24: Trade receivables | C24: 3280.3 | D24: 2565.56 | E24: 1595.94 | F24: 1565.65
A25: (iii) | B25: Cash and cash equivalents | C25: 2671.59 | D25: 1211.31 | E25: 4556.8 | F25: 3111.93
A26: (iv) | B26: Other balances with banks | C26: 183.7 | D26: 1664.62 | E26: 1413.21 | F26: 1032.69
A27: (v) | B27: Loans | C27: 2368.01 | D27: 1865.95 | E27: 81.06 | F27: 24.74
A28: (vi) | B28: Derivative assets | C28: 89.54 | D28: 84.13 | E28: 83.41 | F28: 239.07
A29: (vii) | B29: Other financial assets | C29: 718.3 | D29: 959.96 | E29: 893.81 | F29: 1163.58
A30: (c) | B30: Other assets | C30: 1939.08 | D30: 3770.44 | E30: 3157.45 | F30: 3631.27
B31: Total current assets | C31: =SUM(C21:C30) -> 31289.57 | D31: =SUM(D21:D30) -> 40626.97 | E31: =SUM(E21:E30) -> 37023.06 | F31: =SUM(F21:F30) -> 33702.9
A32: III | B32: Assets held for sale | C32: 0 | D32: 8.23 | E32: 0 | F32: 0
A33: Total assets | C33: =C19+C31+C32 -> 221986.22 | D33: =D19+D31+D32 -> 244419.71 | E33: =E19+E31+E32 -> 247926.35 | F33: =F19+F31+F32 -> 254132.74
A34: Equity and liabilities
A35: IV | B35: Equity
A36: (a) | B36: Equity share capital | C36: 1222.37 | D36: 1222.4 | E36: 1248.6 | F36: 1248.6
A37: (b) | B37: Other equity | C37: 124211.39 | D37: 137787.55 | E37: 139980.87 | F37: 125483.34
B38: Total equity | C38: =SUM(C36:C37) -> 125433.76 | D38: =SUM(D36:D37) -> 139009.95 | E38: =SUM(E36:E37) -> 141229.47 | F38: =SUM(F36:F37) -> 126731.94
A39: V | B39: Non-current liabilities
A40: (a) | B40: Financial liabilities
A41: (i) | B41: Borrowings | C41: 20290.81 | D41: 31568.81 | E41: 36715.91 | F41: 51040.98
...

Sheet P L Statement (TATA STEEL) 
A1: TATA STEEL P/L STATEMENT ANALYSIS
A3: Particulars | B3: FY2023 | C3: FY2024 | D3: FY2025
A4: Sale of products | B4: 139668.73 | C4: 137285.56 | D4: 129303.98
A5: Sale of power and water | B5: 1775.15 | C5: 1800.37 | D5: 1561.54
A6: Other operating revenues | B6: 1469.44 | C6: 1846.72 | D6: 1651.14
A7: Revenue from operations | B7: =SUM(B4:B6) -> 142913.32 | C7: =SUM(C4:C6) -> 140932.65 | D7: =SUM(D4:D6) -> 132516.66
A8: % Change | C8: =(C7/B7-1)*100 -> -1.385924 | D8: =(D7/C7-1)*100 -> -5.9716396
A10: Cost of materials consumed | B10: 59948.72 | C10: 48516.26 | D10: 44088.93
A11: Power, fuel and industrial gases | B11: 6630.38 | C11: 7206.89 | D11: 7111.41
A12: Conversion charges | B12: 3001.01 | C12: 2152.74 | D12: 2409.93
A13: Purchases of SIT | B13: 7424.21 | C13: 9699.77 | D13: 9825.5
A14: Changes in inventories (finished/semi-finished/SIT/WIP) | B14: -1329.69 | C14: 379.91 | D14: 330.66
A15: COGS | B15: =SUM(B10:B14) -> 75674.63 | C15: =SUM(C10:C14) -> 67955.57 | D15: =SUM(D10:D14) -> 63766.43
A16: % Change | C16: =(C15/B15-1)*100 -> -10.200327 | D16: =(D15/C15-1)*100 -> -6.1645278
A18: Gross Profit | B18: =B7-B15 -> 67238.69 | C18: =C7-C15 -> 72977.08 | D18: =D7-D15 -> 68750.23
A19: % Gross Margin | B19: =(B18/B7)*100 -> 47.048582 | C19: =(C18/C7)*100 -> 51.781528 | D19: =(D18/D7)*100 -> 51.880443
A20: % Change (for Gross Profit) | C20: =(C18/B18-1)*100 -> 8.5343572 | D20: =(D18/C18-1)*100 -> -5.792024
A22: Freight and handling charges | B22: 7488.19 | C22: 6737.69 | D22: 7701.74
A23: Commission, discounts and rebates | B23: 295.84 | C23: 286.37 | D23: 338.78
A24: Selling and marketing expenses | B24: =SUM(B22:B23) -> 7784.03 | C24: =SUM(C22:C23) -> 7024.06 | D24: =SUM(D22:D23) -> 8040.52
A25: % Change | C25: =(C24/B24-1)*100 -> -9.7631946 | D25: =(D24/C24-1)*100 -> 14.471118
A27: Consumption of stores and spares | B27: 7217.19 | C27: 6574.23 | D27: 6477.48
A28: Repairs to buildings | B28: 97.33 | C28: 6121.2 | D28: 5857.75
A29: Repairs to machinery | B29: 5344.44
A30: Relining expenses | B30: 232.3 | C30: 229.92 | D30: 204.3
A31: Rent | B31: 91.73 | C31: 379.78 | D31: 462.45
A32: Royalty | B32: 6716.74 | C32: 6511.15 | D32: 5137.08
A33: General expenses | B33: =SUM(B27:B32) -> 19699.73 | C33: =SUM(C27:C32) -> 19816.28 | D33: =SUM(D27:D32) -> 18139.06
A34: % Change | C34: =(C33/B33-1)*100 -> 0.59163247 | D34: =(D33/C33-1)*100 -> -8.4638489
A36: Salaries and wages | B36: 6089.74 | C36: 6173.81 | D36: 6502.3
A37: Contribution to PF and other funds | B37: 619.4 | C37: 640.59 | D37: 671.08
A38: Staff welfare expenses | B38: 511.6 | C38: 658.12 | D38: 836.7
A39: Remuneration to key managerial personnel | B39: 37.82 | C39: 40.59 | D39: 32.91
A40: Tax and rates | B40: 1654.27 | C40: 2340.43 | D40: 1884.44
A41: Insurance | B41: 252.36 | C41: 271.19 | D41: 229.35
A42: Allowance for credit losses/provision for advances | B42: 6.46 | C42: 110.23 | D42: -5.4
A43: Payment to non-executive directors | B43: 9.65 | C43: 8.44 | D43: 7.95
A44: Statutory audit fees | B44: 11.46 | C44: 15.82 | D44: 15.02
A45: Tax audit fees | B45: 1.13 | C45: 1.32 | D45: 1.35
A46: For other services of auditors | B46: 0.93 | C46: 4.14 | D46: 2.75
...
