Workbook

Sheet Theory
B2: Market Multiples | H2: Equity Multiples | N2: Enterprise Multiples
B3: Market multiples (or valuation multiples) are financial ratios used to quickly estimate a company's value by comparing it to similar publicly traded firms or recent industry transactions. They divide a company's market or enterprise value by a specific financial metric (like earnings or revenue) to show what investors are willing to pay per unit of that metric. | H3: These measure the value of the portion of the business belonging strictly to shareholders. The most common metrics use Equity Value (Market Capitalization) in the numerator. | N3: These assess the total value of the business (debt + equity) available to all capital providers. They pair Enterprise Value (EV) in the numerator with metrics unaffected by debt and interest expenses.
B5: Enterprise Value | H5: Price-to-Earnings Ratio (P/E) | N5: EV/EBITDA
B6: Enterprise Value (EV) represents a company's total economic value, effectively acting as the theoretical "takeover price" if an investor were to buy the entire business. Unlike Market Capitalization (which only measures the value of a company's equity), EV reflects the total value of both equity and debt, minus the cash the buyer would inherit. Formula: Market Cap + Total Debt - CCE | H6: Formula: Share Price/Earnings Per Share OR Market Cap/Net Income Earnings Per Share = net profit or loss for the year attributable to equity shareholders of the Parent Company/weighted average number of equity shares outstanding during the year. This measures how much investors are willing to pay for $1 of a company's earnings. | N6: Formula: Enterprise Value/EBITDA The most widely used enterprise multiple because it normalizes profitability across companies with different tax, depreciation, and debt structures.
H8: Price-to-Sales Ratio (P/S) | N8: EV/EBIT
H9: Formula: Share Price/Revenue Per Share OR Market Cap/Total Revenue Revenue Per Share = Total Revenue from operations/weighted average number of equity shares outstanding during the year. This measures how much investors are willing to pay for $1 of a company's earnings. | N9: Formula: Enterprise Value/EBIT Similar to EV/EBITDA, but accounts for depreciation and amortization, making it useful for capital-heavy industries.
N11: EV/Revenue
N12: Formula: Enterprise Value/Total Revenue A strict revenue comparison that ignores profitability entirely.

Sheet ETERNAL P L
A1: ETERNAL P/L STATEMENT
C2: All Figures in ₹ Cr
A3: Particulars | B3: FY2023 | C3: FY2024 | D3: FY2025
A4: Sale of service
A5: Service revenue | B5: 4650 | C5: 6601 | D5: 8592
A6: Royalty income | B6: 13 | C6: 17 | D6: 25
A7: Sale of goods
A8: Revenue from sale of traded goods | B8: 0 | C8: 4 | D8: 0
A9: Other operating revenues | B9: 44 | C9: 0 | D9: 0
A10: Revenue from operations | B10: =SUM(B5:B9) -> 4707 | C10: =SUM(C5:C9) -> 6622 | D10: =SUM(D5:D9) -> 8617
A11: Other Income | B11: 800 | C11: 920 | D11: 1260
A12: Total Income | B12: =SUM(B10:B11) -> 5507 | C12: =SUM(C10:C11) -> 7542 | D12: =SUM(D10:D11) -> 9877
A13: % Change | C13: =(C12/B12-1)*100 -> 36.952969 | D13: =(D12/C12-1)*100 -> 30.959958
A15: Delivery and related charges | B15: 2135 | C15: 2959 | D15: 3788
A16: Payment gateway charges | B16: 137 | C16: 149 | D16: 176
A17: Outsourced support cost | B17: 193 | C17: 102 | D17: 81
A18: Power and fuel | B18: 1 | C18: 2 | D18: 3
A19: Purchases of SIT | B19: 1 | C19: 5 | D19: 0
A20: Changes in inventories (finished/semi-finished/SIT/WIP) | B20: 0 | C20: 0 | D20: 0
A21: COGS | B21: =SUM(B15:B20) -> 2467 | C21: =SUM(C15:C20) -> 3217 | D21: =SUM(D15:D20) -> 4048
A22: % Change | C22: =(C21/B21-1)*100 -> 30.401297 | D22: =(D21/C21-1)*100 -> 25.83152
A24: Gross Profit | B24: =B12-B21 -> 3040 | C24: =C12-C21 -> 4325 | D24: =D12-D21 -> 5829
A25: % Gross Margin | B25: =(B24/B12)*100 -> 55.20247 | C25: =(C24/C12)*100 -> 57.345532 | D25: =(D24/D12)*100 -> 59.015896
A26: % Change (for Gross Profit) | C26: =(C24/B24-1)*100 -> 42.269737 | D26: =(D24/C24-1)*100 -> 34.774566
A28: Advertisement and sales promotion | B28: 1094 | C28: 1233 | D28: 1427
A29: Event infrastructure and artist fee | B29: 0 | C29: 0 | D29: 24
A30: Selling and marketing expenses | B30: =SUM(B28:B29) -> 1094 | C30: =SUM(C28:C29) -> 1233 | D30: =SUM(D28:D29) -> 1451
A31: % Change | C31: =(C30/B30-1)*100 -> 12.705667 | D31: =(D30/C30-1)*100 -> 17.680454
A33: Server and communication cost | B33: 108 | C33: 97 | D33: 123
A34: Rent | B34: 11 | C34: 11 | D34: 30
A35: Repairs and maintenance | B35: 12 | C35: 17 | D35: 19
A36: Postage and courier cost | B36: 11 | C36: 20 | D36: 21
A37: Foreign exchange loss (net) | B37: 0 | C37: 1 | D37: 0
A38: Amount written off (net) | B38: 0 | C38: 0 | D38: 0
A39: Bad debts written-off (net) | B39: 0 | C39: 0 | D39: 0
A40: Provision for doubtful debts and advances | B40: 13 | C40: 50 | D40: 39
A41: Miscellaneous expenses | B41: 26 | C41: 3 | D41: 5
A42: General expenses | B42: =SUM(B33:B41) -> 181 | C42: =SUM(C33:C41) -> 199 | D42: =SUM(D33:D41) -> 237
A43: % Change | C43: =(C42/B42-1)*100 -> 9.9447514 | D43: =(D42/C42-1)*100 -> 19.095477
A45: Salaries and wages | B45: 629 | C45: 595 | D45: 817
...

Sheet ETERNAL BALANCE SHEET
A1: ETERNAL BALANCE SHEET
D2: All Figures in ₹ Cr
A3: Ref | B3: Particulars | C3: FY2023 | D3: FY2024 | E3: FY2025
A4: Assets
A5: I | B5: Non-current assets
A6: (a) | B6: Property, plant and equipment | C6: 59 | D6: 62 | E6: 86
A7: (b) | B7: Capital work-in-progress | C7: 0 | D7: 0 | E7: 0
A8: (c) | B8: Right-of-use assets | C8: 134 | D8: 123 | E8: 151
A9: (d) | B9: Goodwill | C9: 1209 | D9: 1209 | E9: 1209
A10: (e) | B10: Other intangible assets | C10: 0 | D10: 4 | E10: 25
A11: (f) | B11: Financial assets
A12: (i) | B12: Investments | C12: 8862 | D12: 18445 | E12: 24431
A13: (ii) | B13: Loans | C13: 958 | D13: 0 | E13: 880
A14: (iii) | B14: Other financial assets | C14: 1863 | D14: 717 | E14: 2636
A15: (g) | B15: Non-current tax assets (net) | C15: 96 | D15: 176 | E15: 48
A16: (h) | B16: Other assets | C16: 2 | D16: 42 | E16: 74
B17: Total non-current assets | C17: =SUM(C6:C16) -> 13183 | D17: =SUM(D6:D16) -> 20778 | E17: =SUM(E6:E16) -> 29540
A18: II | B18: Current assets
A19: (a) | B19: Inventories | C19: 0 | D19: 0 | E19: 0
A20: (b) | B20: Financial assets
A21: (i) | B21: Investments | C21: 3832 | D21: 927 | E21: 1442
A22: (ii) | B22: Trade receivables | C22: 62 | D22: 69 | E22: 112
A23: (iii) | B23: Cash and cash equivalents | C23: 123 | D23: 181 | E23: 431
A24: (iv) | B24: Other balances with banks | C24: 276 | D24: 278 | E24: 1368
A25: (v) | B25: Other financial assets | C25: 4400 | D25: 2015 | E25: 2753
A26: (c) | B26: Other assets | C26: 51 | D26: 77 | E26: 205
B27: Total current assets | C27: =SUM(C19:C26) -> 8744 | D27: =SUM(D19:D26) -> 3547 | E27: =SUM(E19:E26) -> 6311
A28: Total assets | C28: =C17+C27 -> 21927 | D28: =D17+D27 -> 24325 | E28: =E17+E27 -> 35851
A29: % Change | D29: =(D28/C28-1)*100 -> 10.936289 | E29: =(E28/D28-1)*100 -> 47.38335
A30: Equity and liabilities
A31: IV | B31: Equity
A32: (a) | B32: Equity share capital | C32: 836 | D32: 868 | E32: 907
A33: (b) | B33: Other equity | C33: 19970 | D33: 21907 | E33: 33208
B34: Total equity | C34: =SUM(C32:C33) -> 20806 | D34: =SUM(D32:D33) -> 22775 | E34: =SUM(E32:E33) -> 34115
A35: V | B35: Non-current liabilities
A36: (a) | B36: Financial liabilities
A37: (i) | B37: Lease liabilities | C37: 126 | D37: 107 | E37: 95
A38: (b) | B38: Provisions | C38: 57 | D38: 49 | E38: 62
A39: (c) | B39: Deferred tax liabilities (net) | C39: 0 | D39: 0 | E39: 47
B40: Total non-current liabilities | C40: =SUM(C37:C39) -> 183 | D40: =SUM(D37:D39) -> 156 | E40: =SUM(E37:E39) -> 204
...

Sheet EPS, RPS, MARKET CAP, EV
A1: ETERNAL DILUTED EPS
A3: Particulars | B3: FY2023 | C3: FY2024 | D3: FY2025
A4: Profit attributable to equity holders of the Company (₹) | B4: 1180000000 | C4: 13710000000 | D4: 19600000000
A5: Weighted average number of equity shares in calculating diluted EPS | B5: 8664234819 | C5: 8755246830 | D5: 9135875433
A6: Diluted earnings per share (₹) | B6: =B4/B5 -> 0.13619206 | C6: =C4/C5 -> 1.5659182 | D6: =D4/D5 -> 2.1453883
A8: ETERNAL RPS
A10: Particulars | B10: FY2023 | C10: FY2024 | D10: FY2025
A11: Revenue from operations of the Company (₹) | B11: 47070000000 | C11: 66220000000 | D11: 86170000000
A12: Weighted average number of equity shares | B12: 8664234819 | C12: 8755246830 | D12: 9135875433
A13: RPS (₹) | B13: =B11/B12 -> 5.4326782 | C13: =C11/C12 -> 7.5634647 | D13: =D11/D12 -> 9.4320463
A15: ETERNAL MARKET CAPITALISATION
A17: Particulars | B17: FY2023 | C17: FY2024 | D17: FY2025
A18: Share Price (₹) | B18: 51 | C18: 182.1 | D18: 210.53
A19: Outstanding number of shares at the end of the year () | B19: 8363975413 | C19: 8680255038 | D19: 9072885639
A20: Market Capitalisation (₹) | B20: =B18*B19 -> 426562746063 | C20: =C18*C19 -> 1580674442420 | D20: =D18*D19 -> 1910114613579
A22: ETERNAL ENTERPRISE VALUE
D23: All Figures in ₹ Cr
A24: Particulars | B24: FY2023 | C24: FY2024 | D24: FY2025
A25: Market Cap | B25: 42656 | C25: 158067 | D25: 191011
A26: Non-current lease liabilities | B26: ='ETERNAL BALANCE SHEET'!C37 -> 126 | C26: ='ETERNAL BALANCE SHEET'!D37 -> 107 | D26: ='ETERNAL BALANCE SHEET'!E37 -> 95
A27: Current lease liabilities | B27: ='ETERNAL BALANCE SHEET'!C43 -> 31 | C27: ='ETERNAL BALANCE SHEET'!D43 -> 42 | D27: ='ETERNAL BALANCE SHEET'!E43 -> 78
A28: Total Debt | B28: =SUM(B26:B27) -> 157 | C28: =SUM(C26:C27) -> 149 | D28: =SUM(D26:D27) -> 173
A29: Cash and cash equivalents | B29: ='ETERNAL BALANCE SHEET'!C23 -> 123 | C29: ='ETERNAL BALANCE SHEET'!D23 -> 181 | D29: ='ETERNAL BALANCE SHEET'!E23 -> 431
A30: EV | B30: =(B25+B28)-B29 -> 42690 | C30: =(C25+C28)-C29 -> 158035 | D30: =(D25+D28)-D29 -> 190753

Sheet ETERAL MULTIPLES
A1: ETERNAL MULTIPLES
A3: Multiples | B3: Mathematical formula | C3: FY2023 | D3: FY2024 | E3: FY2025
A4: Equity Multiples
A5: P/E ratio | B5: Share Price/Diluted Earnings Per Share | C5: ='EPS, RPS, MARKET CAP, EV'!B18/'EPS, RPS, MARKET CAP, EV'!B6 -> 374.47117 | D5: ='EPS, RPS, MARKET CAP, EV'!C18/'EPS, RPS, MARKET CAP, EV'!C6 -> 116.2896 | E5: ='EPS, RPS, MARKET CAP, EV'!D18/'EPS, RPS, MARKET CAP, EV'!D6 -> 98.131421
A6: P/S ratio | B6: Share Price/Revenue Per Share | C6: ='EPS, RPS, MARKET CAP, EV'!B18/'EPS, RPS, MARKET CAP, EV'!B13 -> 9.3876349 | D6: ='EPS, RPS, MARKET CAP, EV'!C18/'EPS, RPS, MARKET CAP, EV'!C13 -> 24.076268 | E6: ='EPS, RPS, MARKET CAP, EV'!D18/'EPS, RPS, MARKET CAP, EV'!D13 -> 22.320713
A7: Enterprise Multiples
A8: EV/EBITDA | B8: EV/EBITDA | C8: ='EPS, RPS, MARKET CAP, EV'!B30/'ETERNAL P L'!B64 -> 155.80292 | D8: ='EPS, RPS, MARKET CAP, EV'!C30/'ETERNAL P L'!C64 -> 105.21638 | E8: ='EPS, RPS, MARKET CAP, EV'!D30/'ETERNAL P L'!D64 -> 82.434313
A9: EV/EBIT | B9: EV/EBIT | C9: ='EPS, RPS, MARKET CAP, EV'!B30/'ETERNAL P L'!B73 -> 318.58209 | D9: ='EPS, RPS, MARKET CAP, EV'!C30/'ETERNAL P L'!C73 -> 110.59132 | E9: ='EPS, RPS, MARKET CAP, EV'!D30/'ETERNAL P L'!D73 -> 86.041046
A10: EV/Revenue from operations | B10: EV/Revenue from operations | C10: ='EPS, RPS, MARKET CAP, EV'!B30/'ETERNAL P L'!B10 -> 9.069471 | D10: ='EPS, RPS, MARKET CAP, EV'!C30/'ETERNAL P L'!C10 -> 23.865146 | E10: ='EPS, RPS, MARKET CAP, EV'!D30/'ETERNAL P L'!D10 -> 22.136823

Sheet VALUATION
A1: ASSUMPTIONS/ NOTES
A3: 1. WACC Calculation (for discount rate 'r')
A4: (in crores) | C4: Amount | D4: Weight | E4: Cost of | G4: WACC | H4: =(E6*D6)+(D5*E5*(1-0.25168)) -> 0.094547703
A5: Debt (Pre-Tax) | C5: =63223.39 -> 63223.39 | D5: =(C5/C7) -> 0.33283293 | E5: =D23 -> 0.06703769
A6: Equity | C6: 126731.94 | D6: =(C6/C7) -> 0.66716707 | E6: =D13 -> 0.1166888
A7: Total Capital | C7: =SUM(C5:C6) -> 189955.33 | D7: =SUM(D5:D6) -> 1
A9: Ke (as per CAPM)
A10: Risk-free rate of return | D10: 0.07085 | F10: https://tradingeconomics.com/india/government-bond-yield
A11: Beta | D11: 0.952 | F11: https://www.topstockresearch.com/rt/Stock/TATASTEEL/BetaAndVolatility
A12: Market rate of return | D12: =D16 -> 0.119
A13: Ke | D13: =D10+D11*(D12-D10) -> 0.1166888
A15: 10 year CAGR
A16: - NIFTY 50 | D16: 0.119 | F16: https://www.screener.in/company/NIFTY/
A17: - SENSEX | D17: 0.116 | F17: https://www.screener.in/company/1001/
F18: The Nifty 50 is generally preferred because it is broader (50 stocks vs. 30 in the Sensex).
A19: Kd (as per financial statements)
N20: Debt - Gross debt was significantly higher due to utilisation of various term loans and Debentures during the year majorly for funding capital expansion projects and investments, along with net borrowings of short-term loans during the year
A21: Total Interest Expense | D21: 4238.35
A22: Total Debt | D22: =C5 -> 63223.39
A23: Kd | D23: =D21/D22 -> 0.06703769 | F23: maybe they had taken some of the non-current borrowings towards the end of
F24: the year and its interest was not applicable yet?
F25: Kd seems quite low; increase in finance cost is not up to increase in debt??
A27: 2. Growth rate 'g'
A29: Estimated revenue growth | D29: 0.07 | F29: https://www.alphaspread.com/security/nse/tatasteel/analyst-estimates
A31: For the explicit 4-year forecast period, FCFF is projected to grow directly at a compound annual rate of 7%, matching the consensus Wall Street revenue expansion targets for Tata Steel’s domestic operations.
A32: Have not gone with a line by line forecast as this is driven by substantial near-term volume growth—specifically powered by the newly commissioned 5 MTPA Kalinganagar Phase II expansion.
A33: Operating margins, asset utilization efficiencies, and capital reinvestment rates are conservatively assumed to remain stable at current levels for the foreseeable future.
A34: Consequently, cash flow generation is modeled to scale symmetrically with top-line physical volume expansion
A36: 3. Terminal Growth Rate 't'
A38: Inflation rate | C38: 0.04 | E38: https://www.statista.com/statistics/271322/inflation-rate-in-india/?srsltid=AfmBOoqw4nvLs9ANi6Amduroa8GtGxJ7K9wcrKroQkLWJVmc1jTEJHOv
A39: GDP growth rate | C39: 0.065 | E39: https://www.worldometers.info/gdp/india-gdp/
A41: As businesses scale and reach maximum market penetration, maintaining volume growth becomes harder.
A42: They face threats from new technologies, material substitution, or shifting demographics.
A43: Setting the TGR slightly below nominal GDP (for instance, knocking off 0.5% to 1.5% from the country's total nominal growth projection) builds a safety margin into the valuation.
A44: It forces the model to assume that the company will eventually grow a bit slower than the overall nation as it reaches extreme maturity.
A46: So, in light of this, will assume
A47: Terminal Growth Rate | D47: 0.05
A49: 4. FCFF Calulation
A51: (in crores) | B51: 2022 | C51: 2023 | D51: 2024 | E51: 2025
A52: Net Income | B52: 33011.18 | C52: 14701.36 | D52: 15661.85 | E52: 13969.7
...
